Workbook

Sheet README
B2: CMAS — ตาราง Endpoint ของ API
B3: ทุก path ขึ้นต้นด้วย /api/v1 · สร้างจาก scripts/build-api-endpoints-workbook.py ห้ามแก้ไฟล์นี้ด้วยมือ
B5: จำนวน endpoint
B6: สถานะ | C6: จำนวน | D6: ความหมาย
B7: ทำแล้ว | C7: =COUNTIF(Endpoints!J:J,B7) | D7: มีโค้ดใน app/server/src/modules แล้ว
B8: contract | C8: =COUNTIF(Endpoints!J:J,B8) | D8: อยู่ใน api-design.md §3 ยังไม่มีโค้ด
B9: เสนอใหม่ | C9: =COUNTIF(Endpoints!J:J,B9) | D9: ต้นแบบ index-q.html มีแล้ว แต่ยังไม่อยู่ใน api-design.md — รอรับเข้า contract
B10: หลัง v1 | C10: =COUNTIF(Endpoints!J:J,B10) | D10: อยู่ใน contract แต่เสนอให้เลื่อนไปหลัง v1 (รอ D-5)
B11: รวม | C11: =SUM(C7:C10)
B13: อ่านคอลัมน์อย่างไร
B14: คอลัมน์ | D14: ความหมาย
B15: ใครเรียกได้ | D15: "ผู้สอนของรายวิชา" = ผู้ที่ถูกมอบหมายรายวิชานั้น ผู้สอนทุกคนของวิชามีสิทธิ์เท่ากัน
B16: ตรวจสิทธิ์รายวิชา | D16: "จาก URL" = มี :courseId · "resolve จาก id" = หา courseId จาก id ของแถวก่อน (A-3) · ไม่มีสิทธิ์ได้ 404 เสมอ
B17: Capability | D17: สิทธิ์หนึ่งตัวจากตาราง PERM ของต้นแบบ (17 ตัว) · "อ่าน" = ไม่เปลี่ยนข้อมูล ใช้แค่การตรวจสิทธิ์รายวิชา
B18: ช่วงงาน | D18: P0 ฐาน · P2 รายวิชา · P3 CLO และเกณฑ์ · P5 นักศึกษาและคะแนน · P6 ตัดเกรดและแดชบอร์ด (ดู api-design-plan.md §6)
B19: ต้องมี 0008 | D19: ทำไม่ได้จนกว่า migration 0008 จะเพิ่มตารางหรือคอลัมน์ที่ต้นแบบเสนอ (D-4, D-2)
B20: ประเภท (O–R) | D20: ประเภทการทำงาน · ผลต่อข้อมูล · ประเภทสิทธิ์ · ระดับความระวัง — ความหมายและจำนวนอยู่แผ่น Classification
B21: แผ่น Design | D21: ออกแบบละเอียดรายตัว: query, body, คำตอบ, error, กฎ — ใช้เป็นแบบก่อนเขียนโค้ด · ครบทุก endpoint
B23: ข้อที่ยังต้องตัดสิน
B24: คำถาม | C24: # | D24: ค่าที่ใช้ไปก่อน
B25: ADMIN ทำอะไรได้ในรายวิชาที่ไม่ได้สอน | C25: D-1 | D25: อ่านได้ เขียนไม่ได้ ยกเว้นสร้าง/ลบรายวิชาและจัดการผู้สอน
B26: เก็บ refresh token ที่ไหน เพิกถอนได้ไหม | C26: D-2 | D26: cookie httpOnly หมุนทุกครั้ง และตาราง RefreshToken
B27: สองคนแก้คะแนนช่องเดียวกันพร้อมกัน | C27: D-3 | D27: ส่งค่าเดิมมาด้วย ไม่ตรงกับฐานข้อมูลตอบ 409
B28: รับ 4 ตารางและ 11 คอลัมน์ที่ต้นแบบเสนอหรือไม่ | C28: D-4 | D28: รับทั้งหมดใน migration 0008
B29: v1 มี login ด้วยอีเมลและรหัสผ่านหรือไม่ | C29: D-5 | D29: ไม่มี ใช้ Google อย่างเดียว
B31: ที่มา
B32: docs/markdown/dev/architecture/api-design.md §3 — contract
B33: docs/markdown/dev/planning/api-design-plan.md — กฎ ความปลอดภัย endpoint ที่เสนอเพิ่ม ลำดับงาน
B34: docs/pages/index-q.html — ตาราง PERM และ capOf (ที่มาของ Capability)

Sheet Endpoints
A1: # | B1: กลุ่ม | C1: Method | D1: Path | E1: ทำอะไร | F1: ใครเรียกได้ | G1: ตรวจสิทธิ์รายวิชา | H1: Capability | I1: FR / CR | J1: สถานะ | K1: ช่วงงาน | L1: Issue | M1: ต้องมี 0008 | N1: หมายเหตุ | O1: ประเภทการทำงาน | P1: ผลต่อข้อมูล | Q1: ประเภทสิทธิ์ | R1: ระดับความระวัง
A2: 1 | B2: 1 เข้าสู่ระบบ | C2: POST | D2: /api/v1/auth/google | E2: เข้าสู่ระบบด้วย Google ตรวจ ID token ที่เซิร์ฟเวอร์ | F2: ไม่ต้องล็อกอิน | G2: — | H2: — | I2: FR-01, FR-08 | J2: ทำแล้ว | K2: — | O2: ยืนยันตัวตน | P2: เขียนแถวเดียว | Q2: สาธารณะ | R2: กลาง
A3: 2 | B3: 1 เข้าสู่ระบบ | C3: POST | D3: /api/v1/auth/login | E3: เข้าสู่ระบบด้วยอีเมลและรหัสผ่าน | F3: ไม่ต้องล็อกอิน | G3: — | H3: — | I3: FR-01, FR-03, FR-04 | J3: หลัง v1 | K3: — | N3: รอ D-5 | O3: ยืนยันตัวตน | P3: เขียนแถวเดียว | Q3: สาธารณะ | R3: กลาง
A4: 3 | B4: 1 เข้าสู่ระบบ | C4: POST | D4: /api/v1/auth/refresh | E4: ขอ access token ใหม่ด้วย refresh token | F4: ไม่ต้องล็อกอิน | G4: — | H4: — | I4: FR-01 | J4: contract | K4: P0 | M4: ✓ | N4: ตาราง RefreshToken ตาม D-2 | O4: ยืนยันตัวตน | P4: เขียนแถวเดียว | Q4: สาธารณะ | R4: กลาง
A5: 4 | B5: 1 เข้าสู่ระบบ | C5: POST | D5: /api/v1/auth/logout | E5: ออกจากระบบและเพิกถอน refresh token | F5: ผู้ใช้ที่ล็อกอิน | G5: — | H5: — | I5: FR-01 | J5: contract | K5: P0 | M5: ✓ | N5: ตาราง RefreshToken ตาม D-2 | O5: ยืนยันตัวตน | P5: เขียนแถวเดียว | Q5: ล็อกอินทั่วไป | R5: กลาง
A6: 5 | B6: 1 เข้าสู่ระบบ | C6: GET | D6: /api/v1/auth/me | E6: ข้อมูลและบทบาทของผู้ใช้ที่ล็อกอินอยู่ | F6: ผู้ใช้ที่ล็อกอิน | G6: — | H6: อ่าน | I6: NFR-19 | J6: contract | K6: P0 | O6: อ่านรายการเดียว | P6: อ่านอย่างเดียว | Q6: ล็อกอินทั่วไป | R6: ต่ำ
A7: 6 | B7: 1 เข้าสู่ระบบ | C7: PATCH | D7: /api/v1/auth/password | E7: เปลี่ยนรหัสผ่านของตัวเอง | F7: ผู้ใช้ที่ล็อกอิน | G7: — | H7: — | I7: FR-09 | J7: หลัง v1 | K7: — | N7: รอ D-5 | O7: แก้ไข | P7: เขียนแถวเดียว | Q7: ล็อกอินทั่วไป | R7: กลาง
A8: 7 | B8: 2 บัญชีผู้ใช้ | C8: GET | D8: /api/v1/users | E8: รายการบัญชี กรองด้วย ?status=PENDING หรือ ACTIVE | F8: ADMIN | G8: — | H8: user.manage | I8: FR-05, FR-08b | J8: ทำแล้ว | K8: — | O8: อ่านรายการ | P8: อ่านอย่างเดียว | Q8: ผู้ดูแลระบบ | R8: ต่ำ
A9: 8 | B9: 2 บัญชีผู้ใช้ | C9: PATCH | D9: /api/v1/users/:id/approve | E9: อนุมัติบัญชีที่รออนุมัติ | F9: ADMIN | G9: — | H9: user.manage | I9: FR-08b | J9: ทำแล้ว | K9: — | N9: โค้ดใช้ :id ไม่ใช่ :userId | O9: คำสั่ง | P9: เขียนแถวเดียว | Q9: ผู้ดูแลระบบ | R9: สูง
A10: 9 | B10: 2 บัญชีผู้ใช้ | C10: POST | D10: /api/v1/users | E10: สร้างบัญชีผู้ใช้ | F10: ADMIN | G10: — | H10: user.manage | I10: FR-05 | J10: หลัง v1 | K10: — | N10: รอ D-5 | O10: สร้าง | P10: เขียนแถวเดียว | Q10: ผู้ดูแลระบบ | R10: สูง
A11: 10 | B11: 2 บัญชีผู้ใช้ | C11: GET | D11: /api/v1/users/:userId | E11: รายละเอียดบัญชีหนึ่งคน | F11: ADMIN | G11: — | H11: user.manage | I11: FR-05 | J11: contract | K11: P2 | O11: อ่านรายการเดียว | P11: อ่านอย่างเดียว | Q11: ผู้ดูแลระบบ | R11: ต่ำ
A12: 11 | B12: 2 บัญชีผู้ใช้ | C12: PATCH | D12: /api/v1/users/:userId | E12: แก้ชื่อหรือบทบาทของบัญชี | F12: ADMIN | G12: — | H12: user.manage | I12: FR-05 | J12: contract | K12: P2 | O12: แก้ไข | P12: เขียนแถวเดียว | Q12: ผู้ดูแลระบบ | R12: สูง
A13: 12 | B13: 2 บัญชีผู้ใช้ | C13: PATCH | D13: /api/v1/users/:userId/status | E13: เปิดหรือปิดการใช้งานบัญชี | F13: ADMIN | G13: — | H13: user.manage | I13: FR-03, FR-06 | J13: contract | K13: P2 | O13: แก้ไข | P13: เขียนแถวเดียว | Q13: ผู้ดูแลระบบ | R13: สูง
A14: 13 | B14: 2 บัญชีผู้ใช้ | C14: POST | D14: /api/v1/users/:userId/reset-password | E14: รีเซ็ตรหัสผ่านให้ผู้ใช้ | F14: ADMIN | G14: — | H14: user.manage | I14: FR-07 | J14: หลัง v1 | K14: — | N14: รอ D-5 · ต้องมี mustChangePassword (G-4) | O14: สร้าง | P14: เขียนแถวเดียว | Q14: ผู้ดูแลระบบ | R14: สูง
A15: 14 | B15: 2 บัญชีผู้ใช้ | C15: GET | D15: /api/v1/users/:userId/auth-events | E15: ประวัติบัญชี รวมการถูกปฏิเสธสิทธิ์ | F15: ADMIN | G15: — | H15: user.manage | I15: FR-22b, UC 1.6 | J15: เสนอใหม่ | K15: P5 | M15: ✓ | O15: อ่านรายการ | P15: อ่านอย่างเดียว | Q15: ผู้ดูแลระบบ | R15: ต่ำ
A16: 15 | B16: 3 รายวิชา | C16: GET | D16: /api/v1/courses | E16: รายวิชาที่ผู้เรียกมองเห็น | F16: ผู้ใช้ที่ล็อกอิน | G16: กรองในตัว | H16: อ่าน | I16: FR-24, FR-25 | J16: contract | K16: P2 | L16: #6 | O16: อ่านรายการ | P16: อ่านอย่างเดียว | Q16: ล็อกอินทั่วไป | R16: ต่ำ
A17: 16 | B17: 3 รายวิชา | C17: POST | D17: /api/v1/courses | E17: สร้างรายวิชา ผู้สร้างเป็นผู้สอนใน transaction เดียวกัน | F17: ADMIN · ผู้สอน | G17: — | H17: course.create | I17: FR-20, FR-21, FR-22c, FR-27, FR-28 | J17: contract | K17: P2 | L17: #6 | O17: สร้าง | P17: เขียนหลายแถว (transaction) | Q17: จัดการรายวิชา | R17: กลาง
A18: 17 | B18: 3 รายวิชา | C18: GET | D18: /api/v1/courses/:courseId | E18: รายละเอียดรายวิชา | F18: ผู้สอนของรายวิชา | G18: จาก URL | H18: อ่าน | I18: FR-25 | J18: contract | K18: P2 | L18: #6 | O18: อ่านรายการเดียว | P18: อ่านอย่างเดียว | Q18: อ่านรายวิชา | R18: ต่ำ
A19: 18 | B19: 3 รายวิชา | C19: PATCH | D19: /api/v1/courses/:courseId | E19: แก้ข้อมูลและการตั้งค่ารายวิชา (เกณฑ์ผ่าน วิธีตัดเกรด) | F19: ผู้สอนของรายวิชา | G19: จาก URL | H19: course.settings | I19: FR-20, FR-47, FR-90 | J19: contract | K19: P2 | L19: #6 | O19: แก้ไข | P19: เขียนแถวเดียว | Q19: งานสอน | R19: กลาง
A20: 19 | B20: 3 รายวิชา | C20: DELETE | D20: /api/v1/courses/:courseId | E20: ลบรายวิชา ต้องส่ง ?confirm=true | F20: ADMIN · ผู้สอน | G20: จาก URL | H20: course.delete | I20: FR-26 | J20: contract | K20: P2 | L20: #6 | O20: ลบ | P20: ลบข้อมูล | Q20: จัดการรายวิชา | R20: สูง
A21: 20 | B21: 3 รายวิชา | C21: GET | D21: /api/v1/courses/:courseId/impact | E21: จำนวนข้อมูลที่จะหายถ้าลบรายวิชา | F21: ผู้สอนของรายวิชา | G21: จาก URL | H21: อ่าน | I21: FR-26 | J21: contract | K21: P2 | L21: #6 | O21: อ่านสรุป/คำนวณ | P21: อ่านอย่างเดียว | Q21: อ่านรายวิชา | R21: ต่ำ
A22: 21 | B22: 3 รายวิชา | C22: GET | D22: /api/v1/courses/:courseId/instructors | E22: รายชื่อผู้สอนของรายวิชา | F22: ผู้สอนของรายวิชา | G22: จาก URL | H22: อ่าน | I22: FR-22 | J22: contract | K22: P2 | L22: #6 | O22: อ่านรายการ | P22: อ่านอย่างเดียว | Q22: อ่านรายวิชา | R22: ต่ำ
A23: 22 | B23: 3 รายวิชา | C23: POST | D23: /api/v1/courses/:courseId/instructors | E23: เพิ่มผู้สอนเข้ารายวิชา | F23: ADMIN · ผู้สอน | G23: จาก URL | H23: staff.write | I23: FR-22, FR-23 | J23: contract | K23: P2 | L23: #6 | O23: สร้าง | P23: เขียนแถวเดียว | Q23: จัดการรายวิชา | R23: กลาง
A24: 23 | B24: 3 รายวิชา | C24: DELETE | D24: /api/v1/courses/:courseId/instructors/:userId | E24: เอาผู้สอนออก คนสุดท้ายเอาออกไม่ได้ (422) | F24: ADMIN · ผู้สอน | G24: จาก URL | H24: staff.write | I24: FR-23 | J24: contract | K24: P2 | L24: #6 | N24: S-9 | O24: ลบ | P24: ลบข้อมูล | Q24: จัดการรายวิชา | R24: สูง
A25: 24 | B25: 3 รายวิชา | C25: POST | D25: /api/v1/courses/:courseId/duplicate | E25: คัดลอกรายวิชาเป็นรายวิชาใหม่ | F25: ADMIN · ผู้สอน | G25: จาก URL | H25: course.create | I25: ต้นแบบ | J25: เสนอใหม่ | K25: P2 | O25: คำสั่ง | P25: เขียนหลายแถว (transaction) | Q25: จัดการรายวิชา | R25: กลาง
A26: 25 | B26: 4 CLO และจุดประสงค์ | C26: GET | D26: /api/v1/courses/:courseId/clos | E26: รายการ CLO พร้อมจุดประสงค์ | F26: ผู้สอนของรายวิชา | G26: จาก URL | H26: อ่าน | I26: FR-30, FR-32 | J26: contract | K26: P3 | L26: #7 | O26: อ่านรายการ | P26: อ่านอย่างเดียว | Q26: อ่านรายวิชา | R26: ต่ำ
A27: 26 | B27: 4 CLO และจุดประสงค์ | C27: POST | D27: /api/v1/courses/:courseId/clos | E27: เพิ่ม CLO ต้องเลือกระดับ Bloom เอง ไม่มีค่าตั้งต้น | F27: ผู้สอนของรายวิชา | G27: จาก URL | H27: clo.write | I27: FR-30, FR-31, FR-99, FR-100 | J27: contract | K27: P3 | L27: #7 | O27: สร้าง | P27: เขียนแถวเดียว | Q27: งานสอน | R27: กลาง
A28: 27 | B28: 4 CLO และจุดประสงค์ | C28: PATCH | D28: /api/v1/courses/:courseId/clos/reorder | E28: เรียงลำดับ CLO ใหม่ | F28: ผู้สอนของรายวิชา | G28: จาก URL | H28: clo.write | I28: FR-31 | J28: contract | K28: P3 | L28: #7 | O28: จัดลำดับ | P28: เขียนหลายแถว (transaction) | Q28: งานสอน | R28: กลาง
A29: 28 | B29: 4 CLO และจุดประสงค์ | C29: PATCH | D29: /api/v1/clos/:cloId | E29: แก้ CLO | F29: ผู้สอนของรายวิชา | G29: resolve จาก id | H29: clo.write | I29: FR-30, FR-99, FR-100 | J29: contract | K29: P3 | L29: #7 | O29: แก้ไข | P29: เขียนแถวเดียว | Q29: งานสอน | R29: กลาง
A30: 29 | B30: 4 CLO และจุดประสงค์ | C30: DELETE | D30: /api/v1/clos/:cloId | E30: ลบ CLO เตือนถ้ามีคะแนนอ้างอิง | F30: ผู้สอนของรายวิชา | G30: resolve จาก id | H30: clo.write | I30: FR-36 | J30: contract | K30: P3 | L30: #7 | O30: ลบ | P30: ลบข้อมูล | Q30: งานสอน | R30: สูง
A31: 30 | B31: 4 CLO และจุดประสงค์ | C31: GET | D31: /api/v1/clos/:cloId/objectives | E31: จุดประสงค์เชิงพฤติกรรมของ CLO | F31: ผู้สอนของรายวิชา | G31: resolve จาก id | H31: อ่าน | I31: FR-33 | J31: contract | K31: P3 | L31: #7 | O31: อ่านรายการ | P31: อ่านอย่างเดียว | Q31: อ่านรายวิชา | R31: ต่ำ
A32: 31 | B32: 4 CLO และจุดประสงค์ | C32: POST | D32: /api/v1/clos/:cloId/objectives | E32: เพิ่มจุดประสงค์ | F32: ผู้สอนของรายวิชา | G32: resolve จาก id | H32: clo.write | I32: FR-33 | J32: contract | K32: P3 | L32: #7 | O32: สร้าง | P32: เขียนแถวเดียว | Q32: งานสอน | R32: กลาง
A33: 32 | B33: 4 CLO และจุดประสงค์ | C33: PATCH | D33: /api/v1/objectives/:objectiveId | E33: แก้จุดประสงค์ | F33: ผู้สอนของรายวิชา | G33: resolve จาก id | H33: clo.write | I33: FR-33 | J33: contract | K33: P3 | L33: #7 | O33: แก้ไข | P33: เขียนแถวเดียว | Q33: งานสอน | R33: กลาง
A34: 33 | B34: 4 CLO และจุดประสงค์ | C34: DELETE | D34: /api/v1/objectives/:objectiveId | E34: ลบจุดประสงค์ | F34: ผู้สอนของรายวิชา | G34: resolve จาก id | H34: clo.write | I34: FR-33 | J34: contract | K34: P3 | L34: #7 | O34: ลบ | P34: ลบข้อมูล | Q34: งานสอน | R34: สูง
A35: 34 | B35: 5 กิจกรรมและเกณฑ์ | C35: GET | D35: /api/v1/courses/:courseId/activities | E35: รายการกิจกรรมประเมิน | F35: ผู้สอนของรายวิชา | G35: จาก URL | H35: อ่าน | I35: FR-40, FR-43 | J35: contract | K35: P3 | L35: #7 | M35: ✓ | O35: อ่านรายการ | P35: อ่านอย่างเดียว | Q35: อ่านรายวิชา | R35: ต่ำ
A36: 35 | B36: 5 กิจกรรมและเกณฑ์ | C36: POST | D36: /api/v1/courses/:courseId/activities | E36: เพิ่มกิจกรรม | F36: ผู้สอนของรายวิชา | G36: จาก URL | H36: activity.write | I36: FR-40, FR-41 | J36: contract | K36: P3 | L36: #7 | M36: ✓ | O36: สร้าง | P36: เขียนแถวเดียว | Q36: งานสอน | R36: กลาง
A37: 36 | B37: 5 กิจกรรมและเกณฑ์ | C37: PATCH | D37: /api/v1/courses/:courseId/activities/reorder | E37: เรียงลำดับกิจกรรมใหม่ | F37: ผู้สอนของรายวิชา | G37: จาก URL | H37: activity.write | I37: FR-42 | J37: contract | K37: P3 | L37: #7 | O37: จัดลำดับ | P37: เขียนหลายแถว (transaction) | Q37: งานสอน | R37: กลาง
A38: 37 | B38: 5 กิจกรรมและเกณฑ์ | C38: PATCH | D38: /api/v1/activities/:activityId | E38: แก้กิจกรรม (ชื่อ คะแนนเต็ม น้ำหนัก) | F38: ผู้สอนของรายวิชา | G38: resolve จาก id | H38: activity.write | I38: FR-40, FR-41 | J38: contract | K38: P3 | L38: #7 | M38: ✓ | O38: แก้ไข | P38: เขียนแถวเดียว | Q38: งานสอน | R38: กลาง
A39: 38 | B39: 5 กิจกรรมและเกณฑ์ | C39: DELETE | D39: /api/v1/activities/:activityId | E39: ลบกิจกรรม | F39: ผู้สอนของรายวิชา | G39: resolve จาก id | H39: activity.delete | I39: FR-40 | J39: contract | K39: P3 | L39: #7 | O39: ลบ | P39: ลบข้อมูล | Q39: งานสอน | R39: สูง
A40: 39 | B40: 5 กิจกรรมและเกณฑ์ | C40: GET | D40: /api/v1/courses/:courseId/criteria | E40: เมทริกซ์ กิจกรรม × จุดประสงค์ พร้อมคำเตือน | F40: ผู้สอนของรายวิชา | G40: จาก URL | H40: อ่าน | I40: FR-44, FR-45, FR-48, FR-102 | J40: contract | K40: P3 | L40: #7 | O40: อ่านรายการ | P40: อ่านอย่างเดียว | Q40: อ่านรายวิชา | R40: ต่ำ
...

Sheet Classification
B2: จำแนกประเภท endpoint
B3: นับจากคอลัมน์ O–R ของแผ่น Endpoints (สูตร COUNTIF) · คอลัมน์เหล่านี้สร้างจาก method + path + capability โดยสคริปต์
B6: 1 · ประเภทการทำงาน
B7: ประเภท | C7: ความหมาย | D7: จำนวน
B8: ยืนยันตัวตน | C8: login · refresh · logout | D8: =COUNTIF(Endpoints!O:O,B8)
B9: อ่านรายการ | C9: GET คืนหลายแถว รองรับกรอง/ค้น/แบ่งหน้า | D9: =COUNTIF(Endpoints!O:O,B9)
B10: อ่านรายการเดียว | C10: GET คืนหนึ่งแถวตาม id | D10: =COUNTIF(Endpoints!O:O,B10)
B11: อ่านสรุป/คำนวณ | C11: GET ที่คำนวณจากหลายตาราง (แดชบอร์ด ผลกระทบ ตัดเกรด) | D11: =COUNTIF(Endpoints!O:O,B11)
B12: สร้าง | C12: POST เพิ่มแถวใหม่ | D12: =COUNTIF(Endpoints!O:O,B12)
B13: แก้ไข | C13: PATCH เปลี่ยนบางฟิลด์ของแถวเดียว | D13: =COUNTIF(Endpoints!O:O,B13)
B14: จัดลำดับ | C14: PATCH /reorder เปลี่ยนลำดับหลายแถวพร้อมกัน | D14: =COUNTIF(Endpoints!O:O,B14)
B15: ตั้งค่าทั้งชุด | C15: PUT แทนที่ชุดข้อมูลทั้งชุดของรายวิชา | D15: =COUNTIF(Endpoints!O:O,B15)
B16: ลบ | C16: DELETE | D16: =COUNTIF(Endpoints!O:O,B16)
B17: คำสั่ง | C17: POST/PATCH/DELETE ที่เป็นการเปลี่ยนสถานะ ไม่ใช่ CRUD (อนุมัติ ปิดรับ ถอน คัดลอก ตัดเกรด) | D17: =COUNTIF(Endpoints!O:O,B17)
B18: นำเข้า | C18: อัปโหลด Excel: preview ตรวจ · commit บันทึก | D18: =COUNTIF(Endpoints!O:O,B18)
B19: ส่งออก | C19: ดาวน์โหลดไฟล์ Excel หรือ template | D19: =COUNTIF(Endpoints!O:O,B19)
B20: รวม | D20: =SUM(D8:D19)
B22: 2 · ผลต่อข้อมูล
B23: ประเภท | C23: ความหมาย | D23: จำนวน
B24: อ่านอย่างเดียว | C24: ไม่เปลี่ยนข้อมูล | D24: =COUNTIF(Endpoints!P:P,B24)
B25: เขียนแถวเดียว | C25: เปลี่ยน 1 แถว | D25: =COUNTIF(Endpoints!P:P,B25)
B26: เขียนหลายแถว (transaction) | C26: ต้องสำเร็จทั้งหมดหรือไม่สำเร็จเลย (NFR-11) | D26: =COUNTIF(Endpoints!P:P,B26)
B27: ลบข้อมูล | C27: ลบแถว อาจ cascade | D27: =COUNTIF(Endpoints!P:P,B27)
B28: รวม | D28: =SUM(D24:D27)
B30: 3 · ประเภทสิทธิ์
B31: ประเภท | C31: ความหมาย | D31: จำนวน
B32: สาธารณะ | C32: ไม่ต้องล็อกอิน | D32: =COUNTIF(Endpoints!Q:Q,B32)
B33: ล็อกอินทั่วไป | C33: ผู้ใช้ที่ล็อกอินทุกคน ข้อมูลกรองตามสิทธิ์ในตัว | D33: =COUNTIF(Endpoints!Q:Q,B33)
B34: ผู้ดูแลระบบ | C34: จัดการบัญชีผู้ใช้ (user.manage) | D34: =COUNTIF(Endpoints!Q:Q,B34)
B35: จัดการรายวิชา | C35: สร้าง/ลบรายวิชา จัดการผู้สอน — ADMIN และผู้สอนทำได้ | D35: =COUNTIF(Endpoints!Q:Q,B35)
B36: อ่านรายวิชา | C36: ดูข้อมูลของรายวิชาที่มองเห็น — ADMIN และผู้สอนอ่านได้ | D36: =COUNTIF(Endpoints!Q:Q,B36)
B37: งานสอน | C37: แก้ข้อมูลภายในรายวิชา — ผู้สอนของรายวิชาเท่านั้น ADMIN ทำไม่ได้ (D-1) | D37: =COUNTIF(Endpoints!Q:Q,B37)
B38: รวม | D38: =SUM(D32:D37)
B40: 4 · ระดับความระวัง
B41: ประเภท | C41: ความหมาย | D41: จำนวน
B42: สูง | C42: ลบข้อมูล · ตรึง/ยกเลิกเกรด · นำเข้า commit · จัดการบัญชี · ถอนนักศึกษา | D42: =COUNTIF(Endpoints!R:R,B42)
B43: กลาง | C43: เขียนข้อมูลอื่น ๆ | D43: =COUNTIF(Endpoints!R:R,B43)
B44: ต่ำ | C44: อ่านอย่างเดียว | D44: =COUNTIF(Endpoints!R:R,B44)
B45: รวม | D45: =SUM(D42:D44)

Sheet Design
A1: # | B1: Method | C1: Path | D1: Path / Query | E1: Body (strict) | F1: สำเร็จ | G1: ผิดพลาด | H1: กฎที่ต้องทำตาม | I1: ตรวจใน
A2: 1 | B2: POST | C2: /api/v1/auth/google | D2: — | E2: idToken (string ≥ 1) — ID token จาก Google Sign-In | F2: 200 · ACTIVE → {status:'ACTIVE', user{id, email, name, role}, accessToken, refreshToken} · PENDING → {status:'PENDING', message} | G2: 400 body ผิดรูป · 401 token ปลอม / aud ผิด / email_verified=false / บัญชีถูกปิด (ข้อความเดียวกันทุกกรณี) · 429 | H2: ตรวจ ID token ที่เซิร์ฟเวอร์ (FR-08) · อีเมลนอกโดเมนคณะ → สร้างบัญชี PENDING · บัญชีใหม่เป็น INSTRUCTOR เสมอ · หลัง D-2 refreshToken ย้ายไปเป็น cookie httpOnly (S-2) ไม่อยู่ใน body | I2: ST-AUTH-01, 02, 04
A3: 2 | B3: POST | C3: /api/v1/auth/login | D3: — | E3: — | F3: ไม่ทำใน v1 | G3: — | H3: D-5: v1 เข้าสู่ระบบด้วย Google อย่างเดียว · ถ้าเปิดใช้ภายหลังให้ออกแบบตาม api-design §4 | I3: —
A4: 3 | B4: POST | C4: /api/v1/auth/refresh | D4: — (อ่าน cookie cmas_rt) | E4: — (ไม่มี body) | F4: 200 · {accessToken} + Set-Cookie refresh token ใบใหม่ (หมุนทุกครั้ง) | G4: 401 ไม่มี / หมดอายุ / ปลอม / ถูกเพิกถอน / บัญชีถูกปิด · 401 ใช้ token ที่หมุนไปแล้ว → เพิกถอนทั้งสาย (S-2) · 403 Origin ไม่อยู่ใน allowlist (S-11) | H4: รับเฉพาะ token typ=refresh (S-1) · อ่านแถว User สดทุกครั้ง (NFR-19) · ตาราง RefreshToken (D-2, 0008) | I4: ST-AUTH-05 · ST-ACL-05
A5: 4 | B5: POST | C5: /api/v1/auth/logout | D5: — | E5: — (ไม่มี body) | F5: 200 · {loggedOut:true} + ล้าง cookie | G5: 401 | H5: เพิกถอน refresh token ปัจจุบันในตาราง RefreshToken · access token ที่ออกไปแล้วหมดอายุเองใน 15 นาที — เขียนตามจริง ห้ามอ้างว่าเพิกถอนทันที | I5: ST-AUTH-05
A6: 5 | B6: GET | C6: /api/v1/auth/me | D6: — | E6: — | F6: 200 · {id, email, name, role, status, courseCount} | G6: 401 token หมดอายุ / บัญชีถูกปิดหลังออก token | H6: อ่านแถว User สด ไม่ใช้ claim ใน token (NFR-19) · ไม่ส่ง passwordHash, googleSub (A-9) | I6: ST-ACL-03 · ST-AUTH-07
A7: 6 | B7: PATCH | C7: /api/v1/auth/password | D7: — | E7: — | F7: ไม่ทำใน v1 | G7: — | H7: D-5: v1 เข้าสู่ระบบด้วย Google อย่างเดียว · ถ้าเปิดใช้ภายหลังให้ออกแบบตาม api-design §4 | I7: —
A8: 7 | B8: GET | C8: /api/v1/users | D8: status=PENDING|ACTIVE (มีแล้ว) · ต่อไป: q (ชื่อ/อีเมล), role, isActive, page=1, perPage=20 (≤100) | E8: — | F8: 200 · [{id, email, name, role, status, createdAt}] · เมื่อเพิ่ม page: meta {total, page, perPage} | G8: 400 status ผิดค่า · 401 · 403 ไม่ใช่ ADMIN | H8: user.manage · select เฉพาะฟิลด์ใน DTO (A-9) · ตอนนี้ยังไม่แบ่งหน้า — เพิ่มตาม api-design §2.4 ก่อนจำนวนบัญชีเกิน 100 | I8: ST-AUTH-06
A9: 8 | B9: PATCH | C9: /api/v1/users/:id/approve | D9: :id (โค้ดใช้ :id · contract ใช้ :userId) | E9: — (ไม่มี body) | F9: 200 · ผู้ใช้หลังอนุมัติ status = ACTIVE | G9: 401 · 403 · 404 "ไม่พบผู้ใช้งานนี้" | H9: เปลี่ยนเฉพาะ status ไม่แตะ isActive (ST-AUTH-03) · บันทึก AuthEvent APPROVE เมื่อมีตาราง (S-10, 0008) | I9: ST-AUTH-03
A10: 9 | B10: POST | C10: /api/v1/users | D10: — | E10: — | F10: ไม่ทำใน v1 | G10: — | H10: D-5: v1 เข้าสู่ระบบด้วย Google อย่างเดียว · ถ้าเปิดใช้ภายหลังให้ออกแบบตาม api-design §4 | I10: —
A11: 10 | B11: GET | C11: /api/v1/users/:userId | D11: :userId | E11: — | F11: 200 · {id, email, name, role, status, isActive, authProvider, createdAt, courses[{courseId, code, section, semester, year}], uploadCount} | G11: 401 · 403 · 404 | H11: ไม่ส่ง passwordHash, googleSub (A-9) · courses ใช้ตอบว่า "ลบได้ไหม" (FR-06) | I11: ST-AUTH-07
A12: 11 | B12: PATCH | C12: /api/v1/users/:userId | D12: :userId | E12: name? (1–100) · role? (ADMIN|INSTRUCTOR) · ต้องมีอย่างน้อย 1 ฟิลด์ | F12: 200 · ผู้ใช้หลังแก้ | G12: 400 ว่าง/ฟิลด์เกิน · 403 · 404 · 422 แก้บทบาทของตัวเอง / ลดบทบาทผู้ดูแลที่ใช้งานอยู่คนสุดท้าย / ตั้ง ADMIN ให้คนที่ยังเป็นผู้สอนในรายวิชา (D-1) | H12: user.manage · endpoint เดียวที่รับ role จาก body (ข้อยกเว้นของ A-8) · บันทึก AuthEvent ROLE_CHANGE | I12: ST-AUTH-06
A13: 12 | B13: PATCH | C13: /api/v1/users/:userId/status | D13: :userId | E13: isActive (boolean) | F13: 200 · ผู้ใช้หลังเปลี่ยนสถานะ | G13: 400 · 403 · 404 · 422 ปิดบัญชีตัวเอง / ปิดผู้ดูแลที่ใช้งานอยู่คนสุดท้าย | H13: ไม่มี DELETE /users โดยเจตนา (FR-06) · มีผลใน request ถัดไปทันที เพราะ authMiddleware อ่าน User สด · AuthEvent SUSPEND / ACTIVATE | I13: ST-ACL-03
... A77: 76 | B77: GET | C77: /api/v1/courses/:courseId/dashboard/export | D77: :courseId · scope=course|student, studentId?, format=xlsx | E77: — | F77: 200 · xlsx | G77: 400 scope=student แต่ไม่มี studentId · 403 ADMIN · 404 | H77: service เดียวกับ attainment / at-risk / รายงานรายบุคคล (FR-88) · S-7 · PDF หลัง v1 | I77: ST-CALC-04
B79: ออกแบบครบ 76 จาก 76 endpoint · 4 ตัวเลื่อนไปหลัง v1 (D-5) ระบุไว้ว่าไม่ทำ · ตรวจกับระบบจริงด้วย scripts/check-api-design.py และ app/server/src/api-contract.test.ts

Sheet Rules
A1: # | B1: กฎ | C1: ที่มา
A2: A-1 | B2: Resource เป็นคำนามพหูพจน์ kebab-case ไม่มี verb ใน URL ยกเว้น action ที่ไม่ใช่ CRUD | C2: api-design §1.1
A3: A-2 | B3: ทุก route ที่รับ :courseId เรียก assertCourseAccess() ก่อนแตะข้อมูล ผิดได้ 404 ไม่ใช่ 403 | C3: NFR-07
A4: A-3 | B4: Leaf resource (:cloId, :activityId, :studentId) resolve หา courseId ก่อน แล้วจึงตรวจสิทธิ์ | C4: NFR-07
A5: A-4 | B5: ทุก body, query, params ผ่าน Zod ก่อนถึง service | C5: NFR-13
A6: A-5 | B6: การเขียนหลายแถวอยู่ใน transaction เดียว ยกเว้น import ที่บันทึกเฉพาะแถวที่ผ่าน | C6: NFR-11
A7: A-6 | B7: หนึ่ง route หนึ่ง capability ตรวจผ่าน authorize(cap, courseId, caller) ตัวเดียว route ที่ไม่ประกาศ = test ล้ม | C7: SEC-1, SEC-2
A8: A-7 | B8: ลำดับ preHandler ตายตัว: rate limit → auth → Zod params → resolve courseId → authorize → Zod body → handler | C8: แผน §3
A9: A-8 | B9: Zod .strict() ทุก body · courseId, uploadedBy, changedBy, role, status ไม่รับจาก body | C9: แผน §3
A10: A-9 | B10: ตอบด้วย DTO ที่ select ชัดเจน ไม่ส่ง model ทั้งแถว passwordHash และ googleSub ไม่ออกจาก repository | C10: แผน §3
A11: A-10 | B11: ค่าที่คำนวณได้ (totalPercent, grade, T, attainment) ไม่รับจาก client คำนวณที่ service เดียว | C11: FR-88
A12: A-11 | B12: ตรวจสถานะก่อนเขียน ตอบ 422: กิจกรรมที่ปิดแล้ว นักศึกษาที่ถอนแล้ว เกรดที่ตรึงแล้ว | C12: FR-96
... A14: A-13 | B14: 404 ของ "ไม่มี" กับ "ไม่ใช่ของคุณ" ต้องเหมือนกันทั้ง body และ header | C14: NFR-07

Sheet Security
A1: # | B1: มาตรการ | C1: สถานะ
A2: S-1 | B2: token แยกชนิดด้วย claim typ · authMiddleware รับเฉพาะ access · /auth/refresh รับเฉพาะ refresh | C2: ต้องแก้ (F-2)
A3: S-2 | B3: refresh token เป็น cookie httpOnly, Secure, SameSite=Strict หมุนทุกครั้ง ใช้ซ้ำ = เพิกถอนทั้งสาย | C3: ยังไม่มี · รอ D-2
A4: S-3 | B4: map error ของโดเมนครบ: CourseNotFoundError → 404 · P2002 → 409 · business rule → 422 | C4: ต้องแก้ (F-3)
A5: S-4 | B5: log ไม่มีข้อมูลนักศึกษา: redact ของ pino ไม่ log body log เฉพาะชื่อ error และ request id | C5: ต้องแก้ (F-4)
A6: S-5 | B6: rate limit ราย route: /auth/* 5 ครั้ง/15 นาที ต่อ IP · import 10 ครั้ง/นาที ต่อผู้ใช้ | C6: ยังไม่มี · ตัวเลขเป็นค่าเสนอ
A7: S-6 | B7: ไฟล์นำเข้า: เฉพาะ .xlsx ตรวจ magic bytes · 10 MB · 2,000 แถว 5 ชีต · ไม่ประมวลผลสูตร · ไม่เก็บไฟล์ | C7: มีแค่ขนาดไฟล์
A8: S-7 | B8: ไฟล์ส่งออก: เซลล์ที่ขึ้นต้นด้วย = + - @ ต้องถูกทำให้เป็นข้อความ | C8: ยังไม่มี
A9: S-8 | B9: test ข้ามรายวิชาแบบตาราง: ทุก route ถูกยิงด้วยผู้สอนของวิชาอื่น ต้องได้ 404 | C9: ยังไม่มี
A10: S-9 | B10: ผู้สอนคนสุดท้ายเอาออกไม่ได้ (422) แก้แถวของตัวเองไม่ได้ | C10: อยู่ใน contract
A11: S-10 | B11: การถูกปฏิเสธสิทธิ์บันทึกลง AuthEvent พร้อม capability และรายวิชา | C11: รอ D-4
A12: S-11 | B12: CORS allowlist ตรงตัว · helmet · ตรวจ Origin บน /auth/refresh | C12: CORS และ helmet มีแล้ว
