Workbook

Sheet หน้าปก
B3: สถาบันเทคโนโลยีพระจอมเกล้าเจ้าคุณทหารลาดกระบัง
B4: คณะครุศาสตร์อุตสาหกรรมและเทคโนโลยี
B5: ภาควิชาครุศาสตร์วิศวกรรม
B7: หลักสูตรครุศาสตร์อุตสาหกรรมบัณฑิต สาขาวิชาเทคโนโลยีคอมพิวเตอร์ (หลักสูตรปรับปรุง พ.ศ. 2567)
B9: ระบบติดตามและประเมินผลลัพธ์การเรียนรู้ที่คาดหวังระดับรายวิชา
B10: Course Learning Outcome Monitoring and Assessment System (CMAS)
B12: ตัวอย่างการกรอกข้อมูลของรายวิชา ตามกรอบ มคอ.3 และ มคอ.5
B14: หัวข้อ | C14: รายละเอียด
B15: รายวิชาที่ใช้เป็นตัวอย่าง | C15: 03376120 ระบบฐานข้อมูล (DATABASE SYSTEM) 3 (2-2-5)
B16: แผนการศึกษา | C16: ปีที่ 1 ภาคการศึกษาที่ 1 · หมวดวิชาเฉพาะ · กลุ่มวิชาชีพเฉพาะสาขาวิชา (บังคับเรียน)
B17: ภาคการศึกษา | C17: ภาคการศึกษาที่ 1 ปีการศึกษา 2568 กลุ่มเรียน 01
B18: จำนวน CLO ที่กำหนด | C18: 4 ข้อ
B19: จำนวนกิจกรรมการประเมิน | C19: 5 กิจกรรม (สัดส่วนรวม 100%)
B20: จำนวนนักศึกษาในตัวอย่าง | C20: 8 คน
B22: ลำดับการนำเสนอในไฟล์นี้
B23: แผ่นงาน | C23: ตอบคำถามของอาจารย์ว่า
B24: 1 ข้อมูลรายวิชา | C24: รายวิชานี้คืออะไร และระบบเก็บข้อมูลอะไรบ้างในระดับรายวิชา
B25: 2 CLO | C25: CLO ของรายวิชามีอะไร ระดับพฤติกรรมใด และตั้งเป้าการบรรลุไว้เท่าไร
B26: 3 แผนประเมิน มคอ.3 | C26: แผนการประเมินผลตามแบบ มคอ.3 หมวดที่ 5 — ตารางที่อาจารย์คุ้นเคยอยู่แล้ว
B27: 4 เมทริกซ์ CLO x กิจกรรม | C27: สิ่งที่ระบบเพิ่มจาก มคอ.3 — น้ำหนักรายคู่ ที่ทำให้คำนวณการบรรลุ CLO ได้จริง
B28: 5 รายชื่อนักศึกษา | C28: รายชื่อนักศึกษาที่ต้องนำเข้า
B29: 6 กรอกคะแนน | C29: หน้าจอกรอกคะแนน — งานประจำที่อาจารย์ทำจริงทุกสัปดาห์
B30: 7 ผลการบรรลุ CLO | C30: ผลการบรรลุ CLO รายบุคคล ที่ระบบคำนวณให้ทันทีระหว่างภาคเรียน
B31: 8 ตัดเกรด | C31: การตัดเกรด — อิงเกณฑ์และอิงกลุ่ม บนคะแนนชุดเดียวกัน ให้ผลต่างกันอย่างไร
B32: 9 รายงาน มคอ.5 | C32: ตารางสรุปสำหรับกรอก มคอ.5 — ปลายทางที่ข้อมูลทั้งหมดไปจบ
B33: 10 ตารางฐานข้อมูล | C33: ข้อมูลเดียวกันนี้ถูกเก็บในฐานข้อมูลอย่างไร (สำหรับกรรมการสายเทคนิค)
B34: 11 แผนที่ UI-DB | C34: ช่องกรอกแต่ละช่องลงตารางและคอลัมน์ใด
B36: ที่มาของข้อมูลรายวิชา: รหัสวิชา ชื่อวิชา หน่วยกิต และคำอธิบายรายวิชา นำมาจากเล่มหลักสูตรฉบับปรับปรุง พ.ศ. 2567 โดยตรง · ส่วน CLO กิจกรรมการประเมิน รายชื่อนักศึกษา และคะแนนทั้งหมด เป็นข้อมูลสมมติเพื่อสาธิตการทำงานของระบบเท่านั้น

Sheet 1 ข้อมูลรายวิชา
A1: 1 · ข้อมูลรายวิชา
A2: เทียบได้กับ มคอ.3 หมวดที่ 1 (ข้อมูลทั่วไป) — กรอกครั้งเดียวตอนเปิดรายวิชา
B4: หัวข้อตาม มคอ.3 | C4: ค่าที่กรอกในระบบ | D4: เก็บที่คอลัมน์
B5: รหัสวิชา | C5: 03376120 | D5: Course.code
B6: ชื่อรายวิชา (ไทย) | C6: ระบบฐานข้อมูล | D6: Course.name
B7: ชื่อรายวิชา (อังกฤษ) | C7: DATABASE SYSTEM | D7: Course.nameEn
B8: จำนวนหน่วยกิต | C8: 3 (2-2-5) | D8: Course.credits + lecture/practice/selfStudyHours
B9: หลักสูตรและประเภทของรายวิชา | C9: หมวดวิชาเฉพาะ · กลุ่มวิชาชีพเฉพาะสาขาวิชา (บังคับเรียน) | D9: — ไม่เก็บ (นอกขอบเขต v1)
B10: ภาคการศึกษา / ชั้นปีที่เรียน | C10: ภาคการศึกษาที่ 1 · ปีที่ 1 ภาคการศึกษาที่ 1 | D10: Course.semester
B11: ปีการศึกษา (พ.ศ.) | C11: 2568 | D11: Course.year
B12: กลุ่มเรียน (Section) | C12: 01 | D12: Course.section
B13: รายวิชาที่ต้องเรียนมาก่อน | C13: ไม่มี | D13: — ไม่เก็บ (นอกขอบเขต v1)
B14: อาจารย์ผู้รับผิดชอบรายวิชา | C14: ผศ.วิชัย คงเจริญ (ผู้ประสานงานรายวิชา) | D14: CourseInstructor.role = LEAD
B15: อาจารย์ผู้สอนร่วม | C15: อ.สุดา พรหมมา | D15: CourseInstructor.role = CO
B16: รูปแบบการตัดเกรด | C16: LETTER (A–F) | D16: Course.gradeScale
B17: เกณฑ์คะแนนรวมที่ถือว่าผ่านรายวิชา | C17: 60 | D17: Course.passCriteria
B18: เป้าหมายสัดส่วนผู้ผ่านต่อ CLO (Class Target) | C18: 70 | D18: Course.classTarget
B20: คำอธิบายรายวิชา (ตามเล่มหลักสูตร)
B21: ศึกษาและปฏิบัติในหัวข้อ หลักการของระบบฐานข้อมูล สถาปัตยกรรมฐานข้อมูล โมเดลฐานข้อมูล ฐานข้อมูลเชิงสัมพันธ์ การออกแบบฐานข้อมูล การทำบรรทัดฐาน ภาษาสอบถามเชิงโครงสร้าง ฐานข้อมูลโนเอสคิวแอล
B23: สองบรรทัดสุดท้ายของตารางด้านบนคือค่าที่ระบบใช้ตัดสินผล — เกณฑ์ผ่านรายวิชาใช้กับนักศึกษารายคน ส่วน Class Target ใช้กับภาพรวมทั้งห้องว่า CLO ข้อนั้นบรรลุหรือไม่ ทั้งสองค่าเก็บแยกรายวิชา การแก้ค่าของวิชานี้จึงไม่กระทบผลของวิชาอื่นหรือของภาคเรียนที่ผ่านมา

Sheet 2 CLO
A1: 2 · ผลลัพธ์การเรียนรู้ระดับรายวิชา (CLO)
A2: เทียบได้กับ มคอ.3 หมวดที่ 4 — CLO และเกณฑ์ทั้งหมดเป็นสิ่งที่ผู้สอนกำหนดเองในระดับรายวิชา
A4: ลำดับ | B4: รหัสในระบบ | C4: CLO ที่ | D4: ผลลัพธ์การเรียนรู้ที่คาดหวัง | E4: เกณฑ์ผ่านรายคน (%) | F4: ระดับ Bloom | G4: เป้าหมายผู้ผ่าน (%) | H4: ที่มาของเป้าหมาย
A5: 1 | B5: clo-01 | C5: 1 | D5: ออกแบบฐานข้อมูลเชิงสัมพันธ์จากโจทย์ที่กำหนดได้ | E5: 60 | F5: สร้างสรรค์ (CREATE) | G5: 60 | H5: กำหนดเฉพาะ CLO ข้อนี้
A6: 2 | B6: clo-02 | C6: 2 | D6: เขียนคำสั่งภาษาสอบถามเชิงโครงสร้าง (SQL) เพื่อสืบค้นและจัดการข้อมูลได้ | E6: 60 | F6: ประยุกต์ใช้ (APPLY) | G6: 70 | H6: ใช้ค่าของรายวิชา
A7: 3 | B7: clo-03 | C7: 3 | D7: ทำบรรทัดฐาน (Normalization) ถึงระดับ 3NF ได้ถูกต้อง | E7: 65 | F7: วิเคราะห์ (ANALYZE) | G7: 70 | H7: ใช้ค่าของรายวิชา
A8: 4 | B8: clo-04 | C8: 4 | D8: เลือกใช้ฐานข้อมูลเชิงสัมพันธ์หรือโนเอสคิวแอลได้เหมาะสมกับลักษณะงาน | E8: 60 | F8: ประเมินค่า (EVALUATE) | G8: 65 | H8: กำหนดเฉพาะ CLO ข้อนี้
A10: ระดับ Bloom มาจากคำกริยาที่ขึ้นต้น CLO เอง ไม่ใช่ค่าที่ระบบเดาให้ — ระบบจึงไม่ตั้งค่าเริ่มต้นให้ และผู้สอนต้องเลือกเอง · ประโยชน์คือใช้ตรวจความสอดคล้องของการวัด: CLO ระดับ 'วิเคราะห์' ที่วัดด้วยแบบทดสอบปรนัยอย่างเดียว คือสัญญาณว่าวิธีประเมินยังไม่ตรงกับสิ่งที่เขียนไว้
A11: คอลัมน์ขวาสุดคือสัดส่วนผู้ผ่านที่ทำให้ถือว่า CLO ข้อนั้น 'บรรลุ' · CLO ข้อ 1 อยู่ระดับ 'สร้างสรรค์' ซึ่งเป็นระดับสูงสุดของ Bloom จึงตั้งเป้าไว้ที่ 60% ต่ำกว่าค่ากลางของรายวิชา (70%) อย่างมีเหตุผล · ข้อที่เว้นว่างไว้จะใช้ค่าของรายวิชาโดยอัตโนมัติ
A13: จุดประสงค์เชิงพฤติกรรมของแต่ละ CLO
A14: ลำดับ | B14: รหัสในระบบ | C14: สังกัด CLO | D14: จุดประสงค์เชิงพฤติกรรม
A15: 1 | B15: obj-01 | C15: CLO 1 | D15: เขียนแผนภาพ ER จากความต้องการของผู้ใช้ได้
A16: 2 | B16: obj-02 | C16: CLO 1 | D16: แปลงแผนภาพ ER เป็นตารางเชิงสัมพันธ์ได้
A17: 3 | B17: obj-03 | C17: CLO 2 | D17: เขียนคำสั่ง SELECT พร้อม JOIN หลายตารางได้
A18: 4 | B18: obj-04 | C18: CLO 2 | D18: ใช้ subquery และฟังก์ชันรวม (aggregate function) ได้
A19: 5 | B19: obj-05 | C19: CLO 3 | D19: ระบุความสัมพันธ์เชิงหน้าที่ (functional dependency) ของตารางได้
A20: 6 | B20: obj-06 | C20: CLO 3 | D20: แปลงตารางให้อยู่ในรูปบรรทัดฐานที่ 3 (3NF) ได้
A21: 7 | B21: obj-07 | C21: CLO 4 | D21: เปรียบเทียบข้อดีข้อเสียของฐานข้อมูลเชิงสัมพันธ์กับโนเอสคิวแอลได้

Sheet 3 แผนประเมิน มคอ.3
A1: 3 · แผนการประเมินผลการเรียนรู้
A2: รูปแบบเดียวกับ มคอ.3 หมวดที่ 5 ข้อ 2 — ตารางนี้คือสิ่งที่อาจารย์เขียนอยู่แล้วทุกภาคการศึกษา ระบบเพียงรับข้อมูลชุดเดียวกันนี้เข้าไปเก็บให้เป็นระเบียบ
A4: กิจกรรมที่ | B4: รหัสในระบบ | C4: งาน/กิจกรรมที่ใช้ประเมิน | D4: วิธีการประเมิน | E4: ผลลัพธ์การเรียนรู้ที่ประเมิน | F4: สัปดาห์ที่ประเมิน | G4: คะแนนเต็ม | H4: สัดส่วนการประเมิน (%) | I4: เก็บที่คอลัมน์
A5: 1 | B5: act-01 | C5: แบบทดสอบย่อยครั้งที่ 1 — แผนภาพ ER | D5: สอบย่อย | E5: CLO 1 (100%) | F5: 5 | G5: 20 | H5: 10 | I5: Activity.maxScore / .weight
A6: 2 | B6: act-02 | C6: สอบกลางภาค | D6: สอบข้อเขียน | E6: CLO 1 (40%) · CLO 2 (60%) | F6: 9 | G6: 100 | H6: 30
A7: 3 | B7: act-03 | C7: ปฏิบัติการ SQL (Lab) | D7: ประเมินชิ้นงานปฏิบัติ | E7: CLO 2 (70%) · CLO 3 (30%) | F7: 6-13 | G7: 50 | H7: 20
A8: 4 | B8: act-04 | C8: โครงงานกลุ่ม | D8: ประเมินชิ้นงานและการนำเสนอ | E8: CLO 1 (20%) · CLO 3 (40%) · CLO 4 (40%) | F8: 15 | G8: 100 | H8: 25
A9: 5 | B9: act-05 | C9: สอบปลายภาค | D9: สอบข้อเขียน | E9: CLO 2 (50%) · CLO 3 (50%) | F9: 17 | G9: 100 | H9: 15
C10: รวมสัดส่วนการประเมินทั้งหมด | H10: =SUM(H5:H9) | I10: =IF(H10=100,"ครบ 100 ตามข้อกำหนด","ยังไม่ครบ 100 — ได้ "&H10)
A12: คอลัมน์ 'ผลลัพธ์การเรียนรู้ที่ประเมิน' ใน มคอ.3 ปกติเขียนเพียงว่ากิจกรรมนี้วัด CLO ข้อใดบ้าง แต่ไม่ได้บอกว่าวัดข้อไหนมากน้อยเท่าใด ระบบจึงเพิ่มการระบุน้ำหนักรายคู่ในแผ่นงานถัดไป ซึ่งเป็นเงื่อนไขที่ทำให้คำนวณระดับการบรรลุ CLO ออกมาเป็นตัวเลขได้
A13: ข้อจำกัดที่พบ — คอลัมน์ 'สัปดาห์ที่ประเมิน' (พื้นหลังสีชมพู) เป็นข้อมูลที่ มคอ.3 ต้องมี แต่ฐานข้อมูลของระบบรุ่นปัจจุบันยังไม่มีคอลัมน์รองรับ หากต้องการให้ระบบออกแบบฟอร์ม มคอ.3 ได้ครบถ้วน ต้องเพิ่มคอลัมน์นี้ในตาราง Activity ก่อน

Sheet 4 เมทริกซ์ CLO x กิจกรรม
A1: 4 · เมทริกซ์น้ำหนัก กิจกรรม × CLO
A2: ส่วนที่ระบบเพิ่มจาก มคอ.3 — ระบุว่ากิจกรรมแต่ละอย่างแบ่งไปวัด CLO ข้อใดกี่เปอร์เซ็นต์ แต่ละแถวต้องรวมได้ 100 · ช่องที่เป็น 0 หมายถึงกิจกรรมนั้นไม่ได้วัด CLO ข้อนั้น
A4: กิจกรรมที่ | B4: งาน/กิจกรรมที่ใช้ประเมิน | C4: CLO 1 | D4: CLO 2 | E4: CLO 3 | F4: CLO 4 | G4: รวมแถว | H4: สถานะ
A5: 1 | B5: แบบทดสอบย่อยครั้งที่ 1 — แผนภาพ ER | C5: 100 | D5: 0 | E5: 0 | F5: 0 | G5: =SUM(C5:F5) | H5: =IF(G5=100,"ครบ 100","ผิด — ได้ "&G5)
A6: 2 | B6: สอบกลางภาค | C6: 40 | D6: 60 | E6: 0 | F6: 0 | G6: =SUM(C6:F6) | H6: =IF(G6=100,"ครบ 100","ผิด — ได้ "&G6)
A7: 3 | B7: ปฏิบัติการ SQL (Lab) | C7: 0 | D7: 70 | E7: 30 | F7: 0 | G7: =SUM(C7:F7) | H7: =IF(G7=100,"ครบ 100","ผิด — ได้ "&G7)
A8: 4 | B8: โครงงานกลุ่ม | C8: 20 | D8: 0 | E8: 40 | F8: 40 | G8: =SUM(C8:F8) | H8: =IF(G8=100,"ครบ 100","ผิด — ได้ "&G8)
A9: 5 | B9: สอบปลายภาค | C9: 0 | D9: 50 | E9: 50 | F9: 0 | G9: =SUM(C9:F9) | H9: =IF(G9=100,"ครบ 100","ผิด — ได้ "&G9)
B11: น้ำหนักของ CLO ที่คำนวณได้ (%) | C11: =SUMPRODUCT('3 แผนประเมิน มคอ.3'!$H$5:$H$9,C5:C9)/100 | D11: =SUMPRODUCT('3 แผนประเมิน มคอ.3'!$H$5:$H$9,D5:D9)/100 | E11: =SUMPRODUCT('3 แผนประเมิน มคอ.3'!$H$5:$H$9,E5:E9)/100 | F11: =SUMPRODUCT('3 แผนประเมิน มคอ.3'!$H$5:$H$9,F5:F9)/100 | G11: =SUM(C11:F11) | H11: รวมได้ 100 เสมอ
A13: แถวสีเขียวคือน้ำหนักของ CLO แต่ละข้อเมื่อคิดจากทั้งรายวิชา ซึ่งเป็นค่าที่คำนวณได้เอง อาจารย์ไม่ต้องกรอก และไม่มีการเก็บซ้ำในฐานข้อมูล เพื่อไม่ให้มีวันที่ตัวเลขสองที่ไม่ตรงกัน
A14: เมทริกซ์นี้มี 5×4 = 20 ช่อง แต่มีความสัมพันธ์ที่ต้องเก็บจริงเพียง 10 รายการ

Sheet 5 รายชื่อนักศึกษา
A1: 5 · รายชื่อนักศึกษาในรายวิชา
A2: นำเข้าจากไฟล์ Excel ได้ทั้งชั้น ไม่ต้องพิมพ์ทีละคน
A4: ลำดับ | B4: รหัสในระบบ | C4: รหัสนักศึกษา | D4: ชื่อ-นามสกุล | E4: เก็บที่คอลัมน์
A5: 1 | B5: std-01 | C5: 65010001 | D5: นายกิตติพงษ์ แสงทอง | E5: Student.studentCode / .name
A6: 2 | B6: std-02 | C6: 65010002 | D6: นางสาวจิราพร มีสุข
A7: 3 | B7: std-03 | C7: 65010003 | D7: นายธนกร ศรีสุข
A8: 4 | B8: std-04 | C8: 65010004 | D8: นางสาวปาริชาติ วงศ์ดี
A9: 5 | B9: std-05 | C9: 65010005 | D9: นายภานุวัฒน์ ทองสุข
A10: 6 | B10: std-06 | C10: 65010006 | D10: นางสาวรัตนาภรณ์ ใจงาม
A11: 7 | B11: std-07 | C11: 65010007 | D11: นายวรวุฒิ ชัยมงคล
A12: 8 | B12: std-08 | C12: 65010008 | D12: นางสาวศิริพร แก้วมณี
A14: หนึ่งแถวคือการลงทะเบียนเรียนหนึ่งครั้ง ไม่ใช่ตัวบุคคล — นักศึกษาคนเดียวที่ลงเรียนสามรายวิชา จะปรากฏสามแถวในระบบ ซึ่งเป็นการออกแบบที่ตั้งใจ เพราะคะแนนและผลการบรรลุ CLO ผูกกับรายวิชาเสมอ

Sheet 6 กรอกคะแนน
A1: 6 · หน้าจอกรอกคะแนน
A2: งานประจำที่อาจารย์ทำจริง — กรอกได้ทีละกิจกรรม ไม่ต้องรอให้ครบทุกกิจกรรม
A4: ลำดับ | B4: รหัสนักศึกษา | C4: ชื่อ-นามสกุล | D4: ='3 แผนประเมิน มคอ.3'!C5&" (เต็ม "&'3 แผนประเมิน มคอ.3'!G5&")" | E4: ='3 แผนประเมิน มคอ.3'!C6&" (เต็ม "&'3 แผนประเมิน มคอ.3'!G6&")" | F4: ='3 แผนประเมิน มคอ.3'!C7&" (เต็ม "&'3 แผนประเมิน มคอ.3'!G7&")" | G4: ='3 แผนประเมิน มคอ.3'!C8&" (เต็ม "&'3 แผนประเมิน มคอ.3'!G8&")" | H4: ='3 แผนประเมิน มคอ.3'!C9&" (เต็ม "&'3 แผนประเมิน มคอ.3'!G9&")" | I4: จำนวนแถวที่เกิดในฐานข้อมูล
A5: 1 | B5: 65010001 | C5: นายกิตติพงษ์ แสงทอง | D5: 18 | E5: 85 | F5: 45 | G5: 88 | H5: 82 | I5: 5 แถว — ครบทุกกิจกรรม
A6: 2 | B6: 65010002 | C6: นางสาวจิราพร มีสุข | D6: 15 | E6: 70 | F6: 38 | G6: 75 | H6: 68 | I6: 5 แถว — ครบทุกกิจกรรม
A7: 3 | B7: 65010003 | C7: นายธนกร ศรีสุข | D7: 12 | E7: 55 | F7: 30 | G7: 62 | H7: 58 | I7: 5 แถว — ครบทุกกิจกรรม
A8: 4 | B8: 65010004 | C8: นางสาวปาริชาติ วงศ์ดี | D8: 8 | E8: 42 | F8: 22 | G8: 55 | H8: 40 | I8: 5 แถว — ครบทุกกิจกรรม
A9: 5 | B9: 65010005 | C9: นายภานุวัฒน์ ทองสุข | D9: 20 | E9: 92 | F9: 48 | G9: 95 | H9: 90 | I9: 5 แถว — ครบทุกกิจกรรม
A10: 6 | B10: 65010006 | C10: นางสาวรัตนาภรณ์ ใจงาม | D10: 14 | E10: 65 | G10: 70 | H10: 60 | I10: 4 แถว — ยังไม่ประเมิน 1 กิจกรรม
A11: 7 | B11: 65010007 | C11: นายวรวุฒิ ชัยมงคล | D11: 0 | E11: 38 | F11: 20 | G11: 50 | H11: 35 | I11: 5 แถว — ครบทุกกิจกรรม
A12: 8 | B12: 65010008 | C12: นางสาวศิริพร แก้วมณี | I12: 0 แถว — ยังไม่ประเมิน 5 กิจกรรม
A14: ช่องที่เว้นว่างหมายถึงยังไม่ได้ประเมิน ต่างจากการให้ 0 คะแนนซึ่งหมายถึงประเมินแล้วและได้ 0 จริง ระบบแยกสองกรณีนี้ออกจากกันในทุกการคำนวณ — เปรียบเทียบได้จากนักศึกษารหัส 65010007 ที่ได้ 0 จริง กับรหัส 65010008 ที่ยังไม่ถูกประเมินเลย
A15: กรอกไปแล้ว 34 ช่อง จากทั้งหมด 40 ช่อง — ฐานข้อมูลจึงมีคะแนนอยู่ 34 รายการ ไม่ใช่ 40 รายการ

Sheet 7 ผลการบรรลุ CLO
A1: 7 · ผลการบรรลุ CLO (ระบบคำนวณให้ทั้งหมด)
A2: อาจารย์ไม่ต้องกรอกอะไรในแผ่นนี้ ทุกตัวเลขคำนวณจากคะแนนในแผ่นที่ 6 และน้ำหนักในแผ่นที่ 4 · ลองแก้คะแนนในแผ่นที่ 6 แล้วกลับมาดู ตัวเลขจะเปลี่ยนทันที
A4: ขั้นที่ 1 — สัดส่วนคะแนนที่ทำได้ของแต่ละกิจกรรม
A5: ลำดับ | B5: รหัส | C5: ชื่อ-นามสกุล | D5: กิจกรรมที่ 1 | E5: กิจกรรมที่ 2 | F5: กิจกรรมที่ 3 | G5: กิจกรรมที่ 4 | H5: กิจกรรมที่ 5
A6: 1 | B6: 65010001 | C6: นายกิตติพงษ์ แสงทอง | D6: =IF('6 กรอกคะแนน'!D5="",0,'6 กรอกคะแนน'!D5/'3 แผนประเมิน มคอ.3'!$G$5) | E6: =IF('6 กรอกคะแนน'!E5="",0,'6 กรอกคะแนน'!E5/'3 แผนประเมิน มคอ.3'!$G$6) | F6: =IF('6 กรอกคะแนน'!F5="",0,'6 กรอกคะแนน'!F5/'3 แผนประเมิน มคอ.3'!$G$7) | G6: =IF('6 กรอกคะแนน'!G5="",0,'6 กรอกคะแนน'!G5/'3 แผนประเมิน มคอ.3'!$G$8) | H6: =IF('6 กรอกคะแนน'!H5="",0,'6 กรอกคะแนน'!H5/'3 แผนประเมิน มคอ.3'!$G$9)
A7: 2 | B7: 65010002 | C7: นางสาวจิราพร มีสุข | D7: =IF('6 กรอกคะแนน'!D6="",0,'6 กรอกคะแนน'!D6/'3 แผนประเมิน มคอ.3'!$G$5) | E7: =IF('6 กรอกคะแนน'!E6="",0,'6 กรอกคะแนน'!E6/'3 แผนประเมิน มคอ.3'!$G$6) | F7: =IF('6 กรอกคะแนน'!F6="",0,'6 กรอกคะแนน'!F6/'3 แผนประเมิน มคอ.3'!$G$7) | G7: =IF('6 กรอกคะแนน'!G6="",0,'6 กรอกคะแนน'!G6/'3 แผนประเมิน มคอ.3'!$G$8) | H7: =IF('6 กรอกคะแนน'!H6="",0,'6 กรอกคะแนน'!H6/'3 แผนประเมิน มคอ.3'!$G$9)
A8: 3 | B8: 65010003 | C8: นายธนกร ศรีสุข | D8: =IF('6 กรอกคะแนน'!D7="",0,'6 กรอกคะแนน'!D7/'3 แผนประเมิน มคอ.3'!$G$5) | E8: =IF('6 กรอกคะแนน'!E7="",0,'6 กรอกคะแนน'!E7/'3 แผนประเมิน มคอ.3'!$G$6) | F8: =IF('6 กรอกคะแนน'!F7="",0,'6 กรอกคะแนน'!F7/'3 แผนประเมิน มคอ.3'!$G$7) | G8: =IF('6 กรอกคะแนน'!G7="",0,'6 กรอกคะแนน'!G7/'3 แผนประเมิน มคอ.3'!$G$8) | H8: =IF('6 กรอกคะแนน'!H7="",0,'6 กรอกคะแนน'!H7/'3 แผนประเมิน มคอ.3'!$G$9)
A9: 4 | B9: 65010004 | C9: นางสาวปาริชาติ วงศ์ดี | D9: =IF('6 กรอกคะแนน'!D8="",0,'6 กรอกคะแนน'!D8/'3 แผนประเมิน มคอ.3'!$G$5) | E9: =IF('6 กรอกคะแนน'!E8="",0,'6 กรอกคะแนน'!E8/'3 แผนประเมิน มคอ.3'!$G$6) | F9: =IF('6 กรอกคะแนน'!F8="",0,'6 กรอกคะแนน'!F8/'3 แผนประเมิน มคอ.3'!$G$7) | G9: =IF('6 กรอกคะแนน'!G8="",0,'6 กรอกคะแนน'!G8/'3 แผนประเมิน มคอ.3'!$G$8) | H9: =IF('6 กรอกคะแนน'!H8="",0,'6 กรอกคะแนน'!H8/'3 แผนประเมิน มคอ.3'!$G$9)
A10: 5 | B10: 65010005 | C10: นายภานุวัฒน์ ทองสุข | D10: =IF('6 กรอกคะแนน'!D9="",0,'6 กรอกคะแนน'!D9/'3 แผนประเมิน มคอ.3'!$G$5) | E10: =IF('6 กรอกคะแนน'!E9="",0,'6 กรอกคะแนน'!E9/'3 แผนประเมิน มคอ.3'!$G$6) | F10: =IF('6 กรอกคะแนน'!F9="",0,'6 กรอกคะแนน'!F9/'3 แผนประเมิน มคอ.3'!$G$7) | G10: =IF('6 กรอกคะแนน'!G9="",0,'6 กรอกคะแนน'!G9/'3 แผนประเมิน มคอ.3'!$G$8) | H10: =IF('6 กรอกคะแนน'!H9="",0,'6 กรอกคะแนน'!H9/'3 แผนประเมิน มคอ.3'!$G$9)
A11: 6 | B11: 65010006 | C11: นางสาวรัตนาภรณ์ ใจงาม | D11: =IF('6 กรอกคะแนน'!D10="",0,'6 กรอกคะแนน'!D10/'3 แผนประเมิน มคอ.3'!$G$5) | E11: =IF('6 กรอกคะแนน'!E10="",0,'6 กรอกคะแนน'!E10/'3 แผนประเมิน มคอ.3'!$G$6) | F11: =IF('6 กรอกคะแนน'!F10="",0,'6 กรอกคะแนน'!F10/'3 แผนประเมิน มคอ.3'!$G$7) | G11: =IF('6 กรอกคะแนน'!G10="",0,'6 กรอกคะแนน'!G10/'3 แผนประเมิน มคอ.3'!$G$8) | H11: =IF('6 กรอกคะแนน'!H10="",0,'6 กรอกคะแนน'!H10/'3 แผนประเมิน มคอ.3'!$G$9)
A12: 7 | B12: 65010007 | C12: นายวรวุฒิ ชัยมงคล | D12: =IF('6 กรอกคะแนน'!D11="",0,'6 กรอกคะแนน'!D11/'3 แผนประเมิน มคอ.3'!$G$5) | E12: =IF('6 กรอกคะแนน'!E11="",0,'6 กรอกคะแนน'!E11/'3 แผนประเมิน มคอ.3'!$G$6) | F12: =IF('6 กรอกคะแนน'!F11="",0,'6 กรอกคะแนน'!F11/'3 แผนประเมิน มคอ.3'!$G$7) | G12: =IF('6 กรอกคะแนน'!G11="",0,'6 กรอกคะแนน'!G11/'3 แผนประเมิน มคอ.3'!$G$8) | H12: =IF('6 กรอกคะแนน'!H11="",0,'6 กรอกคะแนน'!H11/'3 แผนประเมิน มคอ.3'!$G$9)
A13: 8 | B13: 65010008 | C13: นางสาวศิริพร แก้วมณี | D13: =IF('6 กรอกคะแนน'!D12="",0,'6 กรอกคะแนน'!D12/'3 แผนประเมิน มคอ.3'!$G$5) | E13: =IF('6 กรอกคะแนน'!E12="",0,'6 กรอกคะแนน'!E12/'3 แผนประเมิน มคอ.3'!$G$6) | F13: =IF('6 กรอกคะแนน'!F12="",0,'6 กรอกคะแนน'!F12/'3 แผนประเมิน มคอ.3'!$G$7) | G13: =IF('6 กรอกคะแนน'!G12="",0,'6 กรอกคะแนน'!G12/'3 แผนประเมิน มคอ.3'!$G$8) | H13: =IF('6 กรอกคะแนน'!H12="",0,'6 กรอกคะแนน'!H12/'3 แผนประเมิน มคอ.3'!$G$9)
A15: ขั้นที่ 2 — ประเมินแล้วหรือยัง (1 = ประเมินแล้ว, 0 = ยังไม่ประเมิน)
A16: ลำดับ | B16: รหัส | C16: ชื่อ-นามสกุล | D16: กิจกรรมที่ 1 | E16: กิจกรรมที่ 2 | F16: กิจกรรมที่ 3 | G16: กิจกรรมที่ 4 | H16: กิจกรรมที่ 5
A17: 1 | B17: 65010001 | C17: นายกิตติพงษ์ แสงทอง | D17: =IF('6 กรอกคะแนน'!D5="",0,1) | E17: =IF('6 กรอกคะแนน'!E5="",0,1) | F17: =IF('6 กรอกคะแนน'!F5="",0,1) | G17: =IF('6 กรอกคะแนน'!G5="",0,1) | H17: =IF('6 กรอกคะแนน'!H5="",0,1)
A18: 2 | B18: 65010002 | C18: นางสาวจิราพร มีสุข | D18: =IF('6 กรอกคะแนน'!D6="",0,1) | E18: =IF('6 กรอกคะแนน'!E6="",0,1) | F18: =IF('6 กรอกคะแนน'!F6="",0,1) | G18: =IF('6 กรอกคะแนน'!G6="",0,1) | H18: =IF('6 กรอกคะแนน'!H6="",0,1)
A19: 3 | B19: 65010003 | C19: นายธนกร ศรีสุข | D19: =IF('6 กรอกคะแนน'!D7="",0,1) | E19: =IF('6 กรอกคะแนน'!E7="",0,1) | F19: =IF('6 กรอกคะแนน'!F7="",0,1) | G19: =IF('6 กรอกคะแนน'!G7="",0,1) | H19: =IF('6 กรอกคะแนน'!H7="",0,1)
A20: 4 | B20: 65010004 | C20: นางสาวปาริชาติ วงศ์ดี | D20: =IF('6 กรอกคะแนน'!D8="",0,1) | E20: =IF('6 กรอกคะแนน'!E8="",0,1) | F20: =IF('6 กรอกคะแนน'!F8="",0,1) | G20: =IF('6 กรอกคะแนน'!G8="",0,1) | H20: =IF('6 กรอกคะแนน'!H8="",0,1)
A21: 5 | B21: 65010005 | C21: นายภานุวัฒน์ ทองสุข | D21: =IF('6 กรอกคะแนน'!D9="",0,1) | E21: =IF('6 กรอกคะแนน'!E9="",0,1) | F21: =IF('6 กรอกคะแนน'!F9="",0,1) | G21: =IF('6 กรอกคะแนน'!G9="",0,1) | H21: =IF('6 กรอกคะแนน'!H9="",0,1)
A22: 6 | B22: 65010006 | C22: นางสาวรัตนาภรณ์ ใจงาม | D22: =IF('6 กรอกคะแนน'!D10="",0,1) | E22: =IF('6 กรอกคะแนน'!E10="",0,1) | F22: =IF('6 กรอกคะแนน'!F10="",0,1) | G22: =IF('6 กรอกคะแนน'!G10="",0,1) | H22: =IF('6 กรอกคะแนน'!H10="",0,1)
A23: 7 | B23: 65010007 | C23: นายวรวุฒิ ชัยมงคล | D23: =IF('6 กรอกคะแนน'!D11="",0,1) | E23: =IF('6 กรอกคะแนน'!E11="",0,1) | F23: =IF('6 กรอกคะแนน'!F11="",0,1) | G23: =IF('6 กรอกคะแนน'!G11="",0,1) | H23: =IF('6 กรอกคะแนน'!H11="",0,1)
A24: 8 | B24: 65010008 | C24: นางสาวศิริพร แก้วมณี | D24: =IF('6 กรอกคะแนน'!D12="",0,1) | E24: =IF('6 กรอกคะแนน'!E12="",0,1) | F24: =IF('6 กรอกคะแนน'!F12="",0,1) | G24: =IF('6 กรอกคะแนน'!G12="",0,1) | H24: =IF('6 กรอกคะแนน'!H12="",0,1)
A26: ขั้นที่ 3 — ตารางน้ำหนักที่ดึงมาจากแผ่นที่ 4
C27: CLO | D27: กิจกรรมที่ 1 | E27: กิจกรรมที่ 2 | F27: กิจกรรมที่ 3 | G27: กิจกรรมที่ 4 | H27: กิจกรรมที่ 5
C28: CLO 1 | D28: ='4 เมทริกซ์ CLO x กิจกรรม'!C5 | E28: ='4 เมทริกซ์ CLO x กิจกรรม'!C6 | F28: ='4 เมทริกซ์ CLO x กิจกรรม'!C7 | G28: ='4 เมทริกซ์ CLO x กิจกรรม'!C8 | H28: ='4 เมทริกซ์ CLO x กิจกรรม'!C9
C29: CLO 2 | D29: ='4 เมทริกซ์ CLO x กิจกรรม'!D5 | E29: ='4 เมทริกซ์ CLO x กิจกรรม'!D6 | F29: ='4 เมทริกซ์ CLO x กิจกรรม'!D7 | G29: ='4 เมทริกซ์ CLO x กิจกรรม'!D8 | H29: ='4 เมทริกซ์ CLO x กิจกรรม'!D9
C30: CLO 3 | D30: ='4 เมทริกซ์ CLO x กิจกรรม'!E5 | E30: ='4 เมทริกซ์ CLO x กิจกรรม'!E6 | F30: ='4 เมทริกซ์ CLO x กิจกรรม'!E7 | G30: ='4 เมทริกซ์ CLO x กิจกรรม'!E8 | H30: ='4 เมทริกซ์ CLO x กิจกรรม'!E9
C31: CLO 4 | D31: ='4 เมทริกซ์ CLO x กิจกรรม'!F5 | E31: ='4 เมทริกซ์ CLO x กิจกรรม'!F6 | F31: ='4 เมทริกซ์ CLO x กิจกรรม'!F7 | G31: ='4 เมทริกซ์ CLO x กิจกรรม'!F8 | H31: ='4 เมทริกซ์ CLO x กิจกรรม'!F9
C32: สัดส่วนของกิจกรรมต่อรายวิชา (%) | D32: ='3 แผนประเมิน มคอ.3'!$H$5 | E32: ='3 แผนประเมิน มคอ.3'!$H$6 | F32: ='3 แผนประเมิน มคอ.3'!$H$7 | G32: ='3 แผนประเมิน มคอ.3'!$H$8 | H32: ='3 แผนประเมิน มคอ.3'!$H$9
C33: เกณฑ์ผ่านของแต่ละ CLO (%) | D33: ='2 CLO'!$E$5 | E33: ='2 CLO'!$E$6 | F33: ='2 CLO'!$E$7 | G33: ='2 CLO'!$E$8
A35: ขั้นที่ 4 — ผลรายบุคคล
A36: ลำดับ | B36: รหัสนักศึกษา | C36: ชื่อ-นามสกุล | D36: CLO 1 (%) | E36: CLO 2 (%) | F36: CLO 3 (%) | G36: CLO 4 (%) | H36: คะแนนรวม (%) | I36: ประเมินแล้วคิดเป็น (%) | J36: กรอกแล้ว | K36: สรุปผลรายวิชา | L36: สถานะการติดตาม
A37: 1 | B37: 65010001 | C37: นายกิตติพงษ์ แสงทอง | D37: =IF(SUMPRODUCT($D$17:$H$17,$D$28:$H$28)=0,"—",SUMPRODUCT($D$6:$H$6,$D$28:$H$28)/SUMPRODUCT($D$17:$H$17,$D$28:$H$28)*100) | E37: =IF(SUMPRODUCT($D$17:$H$17,$D$29:$H$29)=0,"—",SUMPRODUCT($D$6:$H$6,$D$29:$H$29)/SUMPRODUCT($D$17:$H$17,$D$29:$H$29)*100) | F37: =IF(SUMPRODUCT($D$17:$H$17,$D$30:$H$30)=0,"—",SUMPRODUCT($D$6:$H$6,$D$30:$H$30)/SUMPRODUCT($D$17:$H$17,$D$30:$H$30)*100) | G37: =IF(SUMPRODUCT($D$17:$H$17,$D$31:$H$31)=0,"—",SUMPRODUCT($D$6:$H$6,$D$31:$H$31)/SUMPRODUCT($D$17:$H$17,$D$31:$H$31)*100) | H37: =SUMPRODUCT($D$6:$H$6,$D$32:$H$32) | I37: =SUMPRODUCT($D$17:$H$17,$D$32:$H$32) | J37: =COUNT('6 กรอกคะแนน'!D5:H5)&"/5" | K37: =IF(COUNT($D37:$G37)=0,"ยังไม่มีข้อมูล",IF($I37<100,"ยังตัดสินไม่ได้",IF($H37>='1 ข้อมูลรายวิชา'!$C$17,"ผ่าน","ไม่ผ่าน"))) | L37: =IF(COUNT($D37:$G37)=0,"ยังประเมินไม่ครบ",IF(SUMPRODUCT(--ISNUMBER($D37:$G37),--($D37:$G37<$D$33:$G$33))>0,"ต้องติดตามเป็นพิเศษ","ปกติ"))
A38: 2 | B38: 65010002 | C38: นางสาวจิราพร มีสุข | D38: =IF(SUMPRODUCT($D$18:$H$18,$D$28:$H$28)=0,"—",SUMPRODUCT($D$7:$H$7,$D$28:$H$28)/SUMPRODUCT($D$18:$H$18,$D$28:$H$28)*100) | E38: =IF(SUMPRODUCT($D$18:$H$18,$D$29:$H$29)=0,"—",SUMPRODUCT($D$7:$H$7,$D$29:$H$29)/SUMPRODUCT($D$18:$H$18,$D$29:$H$29)*100) | F38: =IF(SUMPRODUCT($D$18:$H$18,$D$30:$H$30)=0,"—",SUMPRODUCT($D$7:$H$7,$D$30:$H$30)/SUMPRODUCT($D$18:$H$18,$D$30:$H$30)*100) | G38: =IF(SUMPRODUCT($D$18:$H$18,$D$31:$H$31)=0,"—",SUMPRODUCT($D$7:$H$7,$D$31:$H$31)/SUMPRODUCT($D$18:$H$18,$D$31:$H$31)*100) | H38: =SUMPRODUCT($D$7:$H$7,$D$32:$H$32) | I38: =SUMPRODUCT($D$18:$H$18,$D$32:$H$32) | J38: =COUNT('6 กรอกคะแนน'!D6:H6)&"/5" | K38: =IF(COUNT($D38:$G38)=0,"ยังไม่มีข้อมูล",IF($I38<100,"ยังตัดสินไม่ได้",IF($H38>='1 ข้อมูลรายวิชา'!$C$17,"ผ่าน","ไม่ผ่าน"))) | L38: =IF(COUNT($D38:$G38)=0,"ยังประเมินไม่ครบ",IF(SUMPRODUCT(--ISNUMBER($D38:$G38),--($D38:$G38<$D$33:$G$33))>0,"ต้องติดตามเป็นพิเศษ","ปกติ"))
A39: 3 | B39: 65010003 | C39: นายธนกร ศรีสุข | D39: =IF(SUMPRODUCT($D$19:$H$19,$D$28:$H$28)=0,"—",SUMPRODUCT($D$8:$H$8,$D$28:$H$28)/SUMPRODUCT($D$19:$H$19,$D$28:$H$28)*100) | E39: =IF(SUMPRODUCT($D$19:$H$19,$D$29:$H$29)=0,"—",SUMPRODUCT($D$8:$H$8,$D$29:$H$29)/SUMPRODUCT($D$19:$H$19,$D$29:$H$29)*100) | F39: =IF(SUMPRODUCT($D$19:$H$19,$D$30:$H$30)=0,"—",SUMPRODUCT($D$8:$H$8,$D$30:$H$30)/SUMPRODUCT($D$19:$H$19,$D$30:$H$30)*100) | G39: =IF(SUMPRODUCT($D$19:$H$19,$D$31:$H$31)=0,"—",SUMPRODUCT($D$8:$H$8,$D$31:$H$31)/SUMPRODUCT($D$19:$H$19,$D$31:$H$31)*100) | H39: =SUMPRODUCT($D$8:$H$8,$D$32:$H$32) | I39: =SUMPRODUCT($D$19:$H$19,$D$32:$H$32) | J39: =COUNT('6 กรอกคะแนน'!D7:H7)&"/5" | K39: =IF(COUNT($D39:$G39)=0,"ยังไม่มีข้อมูล",IF($I39<100,"ยังตัดสินไม่ได้",IF($H39>='1 ข้อมูลรายวิชา'!$C$17,"ผ่าน","ไม่ผ่าน"))) | L39: =IF(COUNT($D39:$G39)=0,"ยังประเมินไม่ครบ",IF(SUMPRODUCT(--ISNUMBER($D39:$G39),--($D39:$G39<$D$33:$G$33))>0,"ต้องติดตามเป็นพิเศษ","ปกติ"))
A40: 4 | B40: 65010004 | C40: นางสาวปาริชาติ วงศ์ดี | D40: =IF(SUMPRODUCT($D$20:$H$20,$D$28:$H$28)=0,"—",SUMPRODUCT($D$9:$H$9,$D$28:$H$28)/SUMPRODUCT($D$20:$H$20,$D$28:$H$28)*100) | E40: =IF(SUMPRODUCT($D$20:$H$20,$D$29:$H$29)=0,"—",SUMPRODUCT($D$9:$H$9,$D$29:$H$29)/SUMPRODUCT($D$20:$H$20,$D$29:$H$29)*100) | F40: =IF(SUMPRODUCT($D$20:$H$20,$D$30:$H$30)=0,"—",SUMPRODUCT($D$9:$H$9,$D$30:$H$30)/SUMPRODUCT($D$20:$H$20,$D$30:$H$30)*100) | G40: =IF(SUMPRODUCT($D$20:$H$20,$D$31:$H$31)=0,"—",SUMPRODUCT($D$9:$H$9,$D$31:$H$31)/SUMPRODUCT($D$20:$H$20,$D$31:$H$31)*100) | H40: =SUMPRODUCT($D$9:$H$9,$D$32:$H$32) | I40: =SUMPRODUCT($D$20:$H$20,$D$32:$H$32) | J40: =COUNT('6 กรอกคะแนน'!D8:H8)&"/5" | K40: =IF(COUNT($D40:$G40)=0,"ยังไม่มีข้อมูล",IF($I40<100,"ยังตัดสินไม่ได้",IF($H40>='1 ข้อมูลรายวิชา'!$C$17,"ผ่าน","ไม่ผ่าน"))) | L40: =IF(COUNT($D40:$G40)=0,"ยังประเมินไม่ครบ",IF(SUMPRODUCT(--ISNUMBER($D40:$G40),--($D40:$G40<$D$33:$G$33))>0,"ต้องติดตามเป็นพิเศษ","ปกติ"))
A41: 5 | B41: 65010005 | C41: นายภานุวัฒน์ ทองสุข | D41: =IF(SUMPRODUCT($D$21:$H$21,$D$28:$H$28)=0,"—",SUMPRODUCT($D$10:$H$10,$D$28:$H$28)/SUMPRODUCT($D$21:$H$21,$D$28:$H$28)*100) | E41: =IF(SUMPRODUCT($D$21:$H$21,$D$29:$H$29)=0,"—",SUMPRODUCT($D$10:$H$10,$D$29:$H$29)/SUMPRODUCT($D$21:$H$21,$D$29:$H$29)*100) | F41: =IF(SUMPRODUCT($D$21:$H$21,$D$30:$H$30)=0,"—",SUMPRODUCT($D$10:$H$10,$D$30:$H$30)/SUMPRODUCT($D$21:$H$21,$D$30:$H$30)*100) | G41: =IF(SUMPRODUCT($D$21:$H$21,$D$31:$H$31)=0,"—",SUMPRODUCT($D$10:$H$10,$D$31:$H$31)/SUMPRODUCT($D$21:$H$21,$D$31:$H$31)*100) | H41: =SUMPRODUCT($D$10:$H$10,$D$32:$H$32) | I41: =SUMPRODUCT($D$21:$H$21,$D$32:$H$32) | J41: =COUNT('6 กรอกคะแนน'!D9:H9)&"/5" | K41: =IF(COUNT($D41:$G41)=0,"ยังไม่มีข้อมูล",IF($I41<100,"ยังตัดสินไม่ได้",IF($H41>='1 ข้อมูลรายวิชา'!$C$17,"ผ่าน","ไม่ผ่าน"))) | L41: =IF(COUNT($D41:$G41)=0,"ยังประเมินไม่ครบ",IF(SUMPRODUCT(--ISNUMBER($D41:$G41),--($D41:$G41<$D$33:$G$33))>0,"ต้องติดตามเป็นพิเศษ","ปกติ"))
A42: 6 | B42: 65010006 | C42: นางสาวรัตนาภรณ์ ใจงาม | D42: =IF(SUMPRODUCT($D$22:$H$22,$D$28:$H$28)=0,"—",SUMPRODUCT($D$11:$H$11,$D$28:$H$28)/SUMPRODUCT($D$22:$H$22,$D$28:$H$28)*100) | E42: =IF(SUMPRODUCT($D$22:$H$22,$D$29:$H$29)=0,"—",SUMPRODUCT($D$11:$H$11,$D$29:$H$29)/SUMPRODUCT($D$22:$H$22,$D$29:$H$29)*100) | F42: =IF(SUMPRODUCT($D$22:$H$22,$D$30:$H$30)=0,"—",SUMPRODUCT($D$11:$H$11,$D$30:$H$30)/SUMPRODUCT($D$22:$H$22,$D$30:$H$30)*100) | G42: =IF(SUMPRODUCT($D$22:$H$22,$D$31:$H$31)=0,"—",SUMPRODUCT($D$11:$H$11,$D$31:$H$31)/SUMPRODUCT($D$22:$H$22,$D$31:$H$31)*100) | H42: =SUMPRODUCT($D$11:$H$11,$D$32:$H$32) | I42: =SUMPRODUCT($D$22:$H$22,$D$32:$H$32) | J42: =COUNT('6 กรอกคะแนน'!D10:H10)&"/5" | K42: =IF(COUNT($D42:$G42)=0,"ยังไม่มีข้อมูล",IF($I42<100,"ยังตัดสินไม่ได้",IF($H42>='1 ข้อมูลรายวิชา'!$C$17,"ผ่าน","ไม่ผ่าน"))) | L42: =IF(COUNT($D42:$G42)=0,"ยังประเมินไม่ครบ",IF(SUMPRODUCT(--ISNUMBER($D42:$G42),--($D42:$G42<$D$33:$G$33))>0,"ต้องติดตามเป็นพิเศษ","ปกติ"))
A43: 7 | B43: 65010007 | C43: นายวรวุฒิ ชัยมงคล | D43: =IF(SUMPRODUCT($D$23:$H$23,$D$28:$H$28)=0,"—",SUMPRODUCT($D$12:$H$12,$D$28:$H$28)/SUMPRODUCT($D$23:$H$23,$D$28:$H$28)*100) | E43: =IF(SUMPRODUCT($D$23:$H$23,$D$29:$H$29)=0,"—",SUMPRODUCT($D$12:$H$12,$D$29:$H$29)/SUMPRODUCT($D$23:$H$23,$D$29:$H$29)*100) | F43: =IF(SUMPRODUCT($D$23:$H$23,$D$30:$H$30)=0,"—",SUMPRODUCT($D$12:$H$12,$D$30:$H$30)/SUMPRODUCT($D$23:$H$23,$D$30:$H$30)*100) | G43: =IF(SUMPRODUCT($D$23:$H$23,$D$31:$H$31)=0,"—",SUMPRODUCT($D$12:$H$12,$D$31:$H$31)/SUMPRODUCT($D$23:$H$23,$D$31:$H$31)*100) | H43: =SUMPRODUCT($D$12:$H$12,$D$32:$H$32) | I43: =SUMPRODUCT($D$23:$H$23,$D$32:$H$32) | J43: =COUNT('6 กรอกคะแนน'!D11:H11)&"/5" | K43: =IF(COUNT($D43:$G43)=0,"ยังไม่มีข้อมูล",IF($I43<100,"ยังตัดสินไม่ได้",IF($H43>='1 ข้อมูลรายวิชา'!$C$17,"ผ่าน","ไม่ผ่าน"))) | L43: =IF(COUNT($D43:$G43)=0,"ยังประเมินไม่ครบ",IF(SUMPRODUCT(--ISNUMBER($D43:$G43),--($D43:$G43<$D$33:$G$33))>0,"ต้องติดตามเป็นพิเศษ","ปกติ"))
A44: 8 | B44: 65010008 | C44: นางสาวศิริพร แก้วมณี | D44: =IF(SUMPRODUCT($D$24:$H$24,$D$28:$H$28)=0,"—",SUMPRODUCT($D$13:$H$13,$D$28:$H$28)/SUMPRODUCT($D$24:$H$24,$D$28:$H$28)*100) | E44: =IF(SUMPRODUCT($D$24:$H$24,$D$29:$H$29)=0,"—",SUMPRODUCT($D$13:$H$13,$D$29:$H$29)/SUMPRODUCT($D$24:$H$24,$D$29:$H$29)*100) | F44: =IF(SUMPRODUCT($D$24:$H$24,$D$30:$H$30)=0,"—",SUMPRODUCT($D$13:$H$13,$D$30:$H$30)/SUMPRODUCT($D$24:$H$24,$D$30:$H$30)*100) | G44: =IF(SUMPRODUCT($D$24:$H$24,$D$31:$H$31)=0,"—",SUMPRODUCT($D$13:$H$13,$D$31:$H$31)/SUMPRODUCT($D$24:$H$24,$D$31:$H$31)*100) | H44: =SUMPRODUCT($D$13:$H$13,$D$32:$H$32) | I44: =SUMPRODUCT($D$24:$H$24,$D$32:$H$32) | J44: =COUNT('6 กรอกคะแนน'!D12:H12)&"/5" | K44: =IF(COUNT($D44:$G44)=0,"ยังไม่มีข้อมูล",IF($I44<100,"ยังตัดสินไม่ได้",IF($H44>='1 ข้อมูลรายวิชา'!$C$17,"ผ่าน","ไม่ผ่าน"))) | L44: =IF(COUNT($D44:$G44)=0,"ยังประเมินไม่ครบ",IF(SUMPRODUCT(--ISNUMBER($D44:$G44),--($D44:$G44<$D$33:$G$33))>0,"ต้องติดตามเป็นพิเศษ","ปกติ"))
...

Sheet 8 ตัดเกรด
A1: 8 · การตัดเกรด — อิงเกณฑ์ และ อิงกลุ่ม
A2: คะแนนชุดเดียวกัน ตัดสองวิธี ได้ผลต่างกัน — แผ่นนี้แสดงให้เห็นว่าทำไมระบบต้องเก็บว่า ตัดด้วยวิธีใดและด้วยค่าสถิติชุดใด ไม่ใช่เก็บแค่ตัวอักษรเกรด
B4: กลุ่มที่นำมาคิด (ประชากรของการตัดเกรด)
B5: รายการ | C5: ค่า | D5: ที่มา
B6: จำนวนที่นำมาคิด (n) | C6: 6 | D6: เฉพาะผู้ที่ประเมินครบทุกกิจกรรม จากทั้งหมด 8 คน
B7: คะแนนเฉลี่ย (mean) | C7: 65.75 | D7: คำนวณจากคะแนนรวมถ่วงน้ำหนักของ n คนนี้
B8: ส่วนเบี่ยงเบนมาตรฐาน (SD) | C8: 20.75 | D8: ถ้าเป็น 0 ระบบจะไม่ยอมให้ตัดอิงกลุ่ม เพราะสูตรต้องหารด้วยค่านี้
B9: คะแนนต่ำสุด / สูงสุด | C9: 37.15 / 94.05 | D9: แสดงประกอบเท่านั้น ไม่มีคอลัมน์เก็บ — หาได้จากคะแนนรวมของ n คนนี้เมื่อไรก็ได้ และไม่มีสูตรใดใช้
B11: ไม่นำมาคิด: นางสาวรัตนาภรณ์ ใจงาม — ยังประเมินไม่ครบ (1 กิจกรรม) · คนที่ยังประเมินไม่ครบต้องไม่ถูกนับใน mean และ SD เพราะคะแนนที่ยังไม่ครบจะดึงค่าเฉลี่ยของทั้งห้องให้ต่ำลงและดันเกรดคนอื่นขึ้นทั้งกลุ่ม
B12: ไม่นำมาคิด: นางสาวศิริพร แก้วมณี — ยังประเมินไม่ครบ (5 กิจกรรม) · คนที่ยังประเมินไม่ครบต้องไม่ถูกนับใน mean และ SD เพราะคะแนนที่ยังไม่ครบจะดึงค่าเฉลี่ยของทั้งห้องให้ต่ำลงและดันเกรดคนอื่นขึ้นทั้งกลุ่ม
B14: ผลการตัดเกรดทั้งสองวิธี บนคะแนนชุดเดียวกัน
B15: รหัสนักศึกษา | C15: ชื่อ-นามสกุล | D15: คะแนนรวม (%) | E15: เกรด อิงเกณฑ์ | F15: T-score | G15: เกรด อิงกลุ่ม | H15: ต่างกัน? | I15: หมายเหตุ
B16: 65010001 | C16: นายกิตติพงษ์ แสงทอง | D16: 86.8 | E16: A | F16: 60.14 | G16: B+ | H16: ต่าง | I16: A → B+
B17: 65010002 | C17: นางสาวจิราพร มีสุข | D17: 72.65 | E17: B | F17: 53.33 | G17: C+ | H17: ต่าง | I17: B → C+
B18: 65010003 | C18: นายธนกร ศรีสุข | D18: 58.7 | E18: D+ | F18: 46.6 | G18: C | H18: ต่าง | I18: D+ → C
B19: 65010004 | C19: นางสาวปาริชาติ วงศ์ดี | D19: 45.15 | E19: F | F19: 40.07 | G19: D+ | H19: ต่าง | I19: F → D+
B20: 65010005 | C20: นายภานุวัฒน์ ทองสุข | D20: 94.05 | E20: A | F20: 63.64 | G20: B+ | H20: ต่าง | I20: A → B+
B21: 65010007 | C21: นายวรวุฒิ ชัยมงคล | D21: 37.15 | E21: F | F21: 36.22 | G21: D | H21: ต่าง | I21: F → D
B23: อิงเกณฑ์: A = 2 · B = 1 · D+ = 1 · F = 2
B24: อิงกลุ่ม: B+ = 2 · C+ = 1 · C = 1 · D+ = 1 · D = 1
B26: นักศึกษา 6 คนจาก 6 คน ได้เกรดไม่เท่ากันระหว่างสองวิธี ทั้งที่คะแนนดิบชุดเดียวกัน · อิงเกณฑ์ตัดสินจากคะแนนของตัวเองล้วน ๆ ส่วนอิงกลุ่มตัดสินจากตำแหน่งเทียบกับเพื่อนร่วมห้อง คนที่ได้ 45 คะแนนจึงตกเมื่อใช้อิงเกณฑ์ แต่ไม่ตกเมื่อใช้อิงกลุ่ม เพราะทั้งห้องคะแนนไม่สูง
B27: เพราะเกรดอิงกลุ่มขึ้นกับ 'ใครอยู่ในห้องวันที่ตัด' ระบบจึงตรึงค่า n / mean / SD ไว้กับผลการตัดเกรด แต่ละรอบ · ถ้าไม่ตรึง นักศึกษาถอนรายวิชาเพียงคนเดียวจะทำให้ค่าเฉลี่ยขยับ และเกรดของ ทุกคนเปลี่ยนตามโดยไม่มีใครแก้คะแนนสักตัว · เกรดที่ประกาศแล้วจะแก้ไม่ได้ ต้องตัดรอบใหม่แทน
B29: เกณฑ์ที่ใช้ตัด
B30: เกรด | C30: อิงเกณฑ์ — คะแนนรวมขั้นต่ำ (%) | D30: อิงกลุ่ม — T-score ขั้นต่ำ
B31: A | C31: 80 | D31: 65
B32: B+ | C32: 75 | D32: 60
B33: B | C33: 70 | D33: 55
B34: C+ | C34: 65 | D34: 50
B35: C | C35: 60 | D35: 45
B36: D+ | C36: 55 | D36: 40
B37: D | C37: 50 | D37: 35
B38: F | C38: 0 | D38: 0
B40: T-score 50 คือค่าเฉลี่ยของห้องพอดี ทุก 10 หน่วยคือ 1 ส่วนเบี่ยงเบนมาตรฐาน · สูตร T = 50 + 10 × (คะแนนของนักศึกษา − ค่าเฉลี่ย) ÷ ส่วนเบี่ยงเบนมาตรฐาน

Sheet 9 รายงาน มคอ.5
A1: 9 · ตารางสรุปสำหรับกรอก มคอ.5
A2: รายงานผลการดำเนินการของรายวิชา — ระบบสรุปให้พร้อมนำไปกรอกในแบบฟอร์ม มคอ.5 โดยไม่ต้องรวบรวมคะแนนจากไฟล์ Excel หลายไฟล์อีก
B4: 03376120 ระบบฐานข้อมูล · ภาคการศึกษาที่ 1 ปีการศึกษา 2568 · กลุ่มเรียน 01
B6: ผลการดำเนินการตามผลลัพธ์การเรียนรู้ของรายวิชา
B7: CLO ที่ | C7: ผลลัพธ์การเรียนรู้ที่คาดหวัง | D7: ระดับ Bloom | E7: เกณฑ์ผ่านรายบุคคล (%) | F7: เป้าหมายระดับชั้น (%) | G7: ผลที่ได้จริง (%) | H7: จำนวนที่ผ่าน / ประเมินได้ | I7: สรุปผล
B8: CLO 1 | C8: ออกแบบฐานข้อมูลเชิงสัมพันธ์จากโจทย์ที่กำหนดได้ | D8: สร้างสรรค์ | E8: ='2 CLO'!$E$5 | F8: ='2 CLO'!$G$5 | G8: =IF(COUNT('7 ผลการบรรลุ CLO'!D37:D44)=0,"—",COUNTIF('7 ผลการบรรลุ CLO'!D37:D44,">="&E8)/COUNT('7 ผลการบรรลุ CLO'!D37:D44)*100) | H8: =COUNTIF('7 ผลการบรรลุ CLO'!D37:D44,">="&E8)&" / "&COUNT('7 ผลการบรรลุ CLO'!D37:D44) | I8: =IF(G8="—","ยังสรุปไม่ได้",IF(G8>=F8,"บรรลุตามเป้าหมาย","ยังไม่บรรลุ — ต้องทบทวนการจัดการเรียนการสอน"))
B9: CLO 2 | C9: เขียนคำสั่งภาษาสอบถามเชิงโครงสร้าง (SQL) เพื่อสืบค้นและจัดการข้อมูลได้ | D9: ประยุกต์ใช้ | E9: ='2 CLO'!$E$6 | F9: ='2 CLO'!$G$6 | G9: =IF(COUNT('7 ผลการบรรลุ CLO'!E37:E44)=0,"—",COUNTIF('7 ผลการบรรลุ CLO'!E37:E44,">="&E9)/COUNT('7 ผลการบรรลุ CLO'!E37:E44)*100) | H9: =COUNTIF('7 ผลการบรรลุ CLO'!E37:E44,">="&E9)&" / "&COUNT('7 ผลการบรรลุ CLO'!E37:E44) | I9: =IF(G9="—","ยังสรุปไม่ได้",IF(G9>=F9,"บรรลุตามเป้าหมาย","ยังไม่บรรลุ — ต้องทบทวนการจัดการเรียนการสอน"))
B10: CLO 3 | C10: ทำบรรทัดฐาน (Normalization) ถึงระดับ 3NF ได้ถูกต้อง | D10: วิเคราะห์ | E10: ='2 CLO'!$E$7 | F10: ='2 CLO'!$G$7 | G10: =IF(COUNT('7 ผลการบรรลุ CLO'!F37:F44)=0,"—",COUNTIF('7 ผลการบรรลุ CLO'!F37:F44,">="&E10)/COUNT('7 ผลการบรรลุ CLO'!F37:F44)*100) | H10: =COUNTIF('7 ผลการบรรลุ CLO'!F37:F44,">="&E10)&" / "&COUNT('7 ผลการบรรลุ CLO'!F37:F44) | I10: =IF(G10="—","ยังสรุปไม่ได้",IF(G10>=F10,"บรรลุตามเป้าหมาย","ยังไม่บรรลุ — ต้องทบทวนการจัดการเรียนการสอน"))
B11: CLO 4 | C11: เลือกใช้ฐานข้อมูลเชิงสัมพันธ์หรือโนเอสคิวแอลได้เหมาะสมกับลักษณะงาน | D11: ประเมินค่า | E11: ='2 CLO'!$E$8 | F11: ='2 CLO'!$G$8 | G11: =IF(COUNT('7 ผลการบรรลุ CLO'!G37:G44)=0,"—",COUNTIF('7 ผลการบรรลุ CLO'!G37:G44,">="&E11)/COUNT('7 ผลการบรรลุ CLO'!G37:G44)*100) | H11: =COUNTIF('7 ผลการบรรลุ CLO'!G37:G44,">="&E11)&" / "&COUNT('7 ผลการบรรลุ CLO'!G37:G44) | I11: =IF(G11="—","ยังสรุปไม่ได้",IF(G11>=F11,"บรรลุตามเป้าหมาย","ยังไม่บรรลุ — ต้องทบทวนการจัดการเรียนการสอน"))
B13: สรุปจำนวนนักศึกษา
B14: รายการ | C14: จำนวน (คน)
B15: นักศึกษาทั้งหมดในรายวิชา | G15: =COUNTA('7 ผลการบรรลุ CLO'!B37:B44)
B16: ประเมินครบทุกกิจกรรมแล้ว | G16: =COUNTIF('7 ผลการบรรลุ CLO'!I37:I44,100)
B17: ยังประเมินไม่ครบ | G17: =COUNTIF('7 ผลการบรรลุ CLO'!L37:L44,"ยังประเมินไม่ครบ")
B18: ต้องติดตามเป็นพิเศษ (ยังไม่บรรลุ CLO อย่างน้อย 1 ข้อ) | G18: =COUNTIF('7 ผลการบรรลุ CLO'!L37:L44,"ต้องติดตามเป็นพิเศษ")
B19: ผ่านรายวิชาแล้ว | G19: =COUNTIF('7 ผลการบรรลุ CLO'!K37:K44,"ผ่าน")
B21: ตัวเลขทุกช่องในแผ่นนี้เชื่อมกับคะแนนในแผ่นที่ 6 โดยตรง เมื่อกรอกคะแนนเพิ่ม ตัวเลขจะปรับเอง อาจารย์จึงเปิดดูสถานะการบรรลุ CLO ได้ทุกสัปดาห์ ไม่ต้องรอสิ้นภาคการศึกษา ซึ่งเป็นข้อแตกต่างหลักจากการรวมคะแนนด้วย Excel แบบเดิม

Sheet 10 ตารางฐานข้อมูล
A1: 10 · ข้อมูลเดียวกันนี้ถูกเก็บในฐานข้อมูลอย่างไร
A2: ทั้ง 13 ตาราง 80 คอลัมน์ ตามแผนภาพ ER ของระบบ พร้อมแถวข้อมูลที่ตรงกับทุกแผ่นงานก่อนหน้า — แต่ละตารางแสดงชื่อคอลัมน์ ชนิดข้อมูล และบทบาทของคีย์ครบทุกช่อง
B4: ความหมายของแถบสีในแถว KEY : PK = คีย์หลัก · FK = คีย์อ้างอิงไปตารางอื่น · UQ = ห้ามซ้ำ · GEN = คอลัมน์ที่ฐานข้อมูลสร้างให้เอง · NULL = ยังไม่มีค่า
B6: User — 8 คอลัมน์ · 3 แถว
B7: เก็บอะไร: บัญชีผู้ใช้ระบบและบทบาท · กรอกจากแผ่นงาน: ผู้ดูแลระบบสร้างให้
B8: id | C8: email | D8: name | E8: passwordHash | F8: role | G8: isActive | H8: createdAt | I8: updatedAt
B9: VARCHAR(30) | C9: VARCHAR(255) | D9: VARCHAR(255) | E9: VARCHAR(255) | F9: ENUM('ADMIN','INSTRUCTOR') | G9: TINYINT(1) | H9: DATETIME(3) | I9: DATETIME(3)
B10: PK | C10: UQ
B11: usr-01 | C11: admin@kmitl.ac.th | D11: อ.ดร.สมชาย ใจดี | E11: $argon2id$v=19$m=65536,t=3,p=4$… | F11: ADMIN | G11: 1 | H11: 2025-05-15 08:30:00 | I11: 2025-05-15 08:30:00
B12: usr-02 | C12: wichai.k@kmitl.ac.th | D12: ผศ.วิชัย คงเจริญ | E12: $argon2id$v=19$m=65536,t=3,p=4$… | F12: INSTRUCTOR | G12: 1 | H12: 2025-05-15 08:30:00 | I12: 2025-05-15 08:30:00
B13: usr-03 | C13: suda.p@kmitl.ac.th | D13: อ.สุดา พรหมมา | E13: $argon2id$v=19$m=65536,t=3,p=4$… | F13: INSTRUCTOR | G13: 1 | H13: 2025-05-15 08:30:00 | I13: 2025-05-15 08:30:00
B14: passwordHash เก็บเฉพาะค่าที่ผ่านการเข้ารหัสด้วย argon2 แล้ว ระบบไม่เคยเก็บรหัสผ่านจริง และไม่มีทางถอดกลับได้ · isActive = 0 คือปิดบัญชี ใช้แทนการลบเสมอ
B17: Course — 16 คอลัมน์ · 1 แถว
B18: เก็บอะไร: รายวิชา — เป็นรากของข้อมูลทั้งหมด ไม่มีตารางใดอยู่เหนือกว่านี้ · กรอกจากแผ่นงาน: 1 ข้อมูลรายวิชา
B19: id | C19: code | D19: name | E19: nameEn | F19: semester | G19: year | H19: section | I19: credits | J19: lectureHours | K19: practiceHours | L19: selfStudyHours | M19: gradeScale | N19: passCriteria | O19: classTarget | P19: createdAt | Q19: updatedAt
B20: VARCHAR(30) | C20: VARCHAR(50) | D20: VARCHAR(255) | E20: VARCHAR(255) | F20: INT | G20: INT | H20: VARCHAR(10) | I20: DECIMAL(3,1) | J20: DECIMAL(4,1) | K20: DECIMAL(4,1) | L20: DECIMAL(4,1) | M20: ENUM('LETTER','PASS_FAIL') | N20: DOUBLE | O20: DOUBLE | P20: DATETIME(3) | Q20: DATETIME(3)
B21: PK | C21: UQ | F21: UQ | G21: UQ | H21: UQ
B22: crs-01 | C22: 03376120 | D22: ระบบฐานข้อมูล | E22: DATABASE SYSTEM | F22: 1 | G22: 2568 | H22: 01 | I22: 3 | J22: 2 | K22: 2 | L22: 5 | M22: LETTER | N22: 60 | O22: 70 | P22: 2025-05-20 10:15:00 | Q22: 2025-06-02 14:05:00
B23: หน่วยกิต 3 (2-2-5) ถูกแยกเก็บเป็นสี่คอลัมน์ คือ credits / lectureHours / practiceHours / selfStudyHours เพื่อให้คำนวณและตรวจสอบได้ · code + semester + year + section รวมกันต้องไม่ซ้ำ จึงเปิดวิชาเดียวกันหลายกลุ่มเรียนในเทอมเดียวได้ · year เก็บเป็น พ.ศ. (2568) ส่วนคอลัมน์ DATETIME ทั้งหมดเป็นเวลาจริงแบบ ค.ศ.
B26: CourseInstructor — 5 คอลัมน์ · 2 แถว
B27: เก็บอะไร: ใครสอนวิชาไหน ในบทบาทใด (ตารางเชื่อม User กับ Course) · กรอกจากแผ่นงาน: 1 ข้อมูลรายวิชา
B28: id | C28: courseId | D28: userId | E28: role | F28: assignedAt
B29: VARCHAR(30) | C29: VARCHAR(30) | D29: VARCHAR(30) | E29: ENUM('LEAD','CO','ASSISTANT') | F29: DATETIME(3)
B30: PK | C30: FK | D30: FK
B31: ci-01 | C31: crs-01 | D31: usr-02 | E31: LEAD | F31: 2025-06-01 09:00:00
B32: ci-02 | C32: crs-01 | D32: usr-03 | E32: CO | F32: 2025-06-01 09:00:00
B33: กฎ 'หนึ่งรายวิชามี LEAD ได้ไม่เกินหนึ่งคน' ไม่ได้เก็บเป็นคอลัมน์ — PostgreSQL บังคับด้วย partial unique index บน courseId เฉพาะแถวที่ role = LEAD · ส่วน 'ต้องมีอย่างน้อยหนึ่งคน' บังคับที่ชั้นแอปพลิเคชัน เพราะแถวรายวิชาต้องมีอยู่ก่อนจึงจะมอบหมายใครได้
B36: CLO — 7 คอลัมน์ · 4 แถว
B37: เก็บอะไร: ผลลัพธ์การเรียนรู้ของรายวิชา พร้อมเกณฑ์ผ่านรายบุคคล · กรอกจากแผ่นงาน: 2 CLO
B38: id | C38: courseId | D38: number | E38: description | F38: threshold | G38: bloomLevel | H38: classTarget
B39: VARCHAR(30) | C39: VARCHAR(30) | D39: INT | E39: VARCHAR(1000) | F39: DOUBLE | G39: ENUM(6 ระดับ) | H39: DOUBLE
B40: PK | C40: FK | D40: UQ | G40: NULL | H40: NULL
B41: clo-01 | C41: crs-01 | D41: 1 | E41: ออกแบบฐานข้อมูลเชิงสัมพันธ์จากโจทย์ที่กำหนดได้ | F41: 60 | G41: CREATE | H41: 60
B42: clo-02 | C42: crs-01 | D42: 2 | E42: เขียนคำสั่งภาษาสอบถามเชิงโครงสร้าง (SQL) เพื่อสืบค้นและจัดการข้อมูลได้ | F42: 60 | G42: APPLY | H42: — ว่าง —
B43: clo-03 | C43: crs-01 | D43: 3 | E43: ทำบรรทัดฐาน (Normalization) ถึงระดับ 3NF ได้ถูกต้อง | F43: 65 | G43: ANALYZE | H43: — ว่าง —
B44: clo-04 | C44: crs-01 | D44: 4 | E44: เลือกใช้ฐานข้อมูลเชิงสัมพันธ์หรือโนเอสคิวแอลได้เหมาะสมกับลักษณะงาน | F44: 60 | G44: EVALUATE | H44: 65
B45: courseId + number ห้ามซ้ำ — ถ้ามี CLO 1 สองแถวในวิชาเดียวกัน รายงานการบรรลุจะผิดทั้งฉบับโดยไม่มีสัญญาณเตือน
B46: bloomLevel ไม่มีค่าเริ่มต้นโดยตั้งใจ — การเดาให้เป็น 'จำ' ทุกแถวจะทำให้คอลัมน์นี้หมดประโยชน์ ทันที เพราะมีไว้ตรวจว่าวิธีวัดตรงกับระดับพฤติกรรมที่เขียนไว้หรือไม่ · classTarget ที่เว้นว่าง หมายถึงใช้ค่าของรายวิชา ไม่ใช่ศูนย์
B49: BehavioralObjective — 4 คอลัมน์ · 7 แถว
B50: เก็บอะไร: จุดประสงค์เชิงพฤติกรรมที่ย่อยลงมาจาก CLO · กรอกจากแผ่นงาน: 2 CLO
...

Sheet 11 แผนที่ UI-DB
A1: 11 · ช่องกรอกแต่ละช่องเก็บที่ไหน
A2: ใช้ตอบคำถามว่าข้อมูลที่กรอกไปอยู่ที่ใด และค่าใดที่ระบบคำนวณให้โดยไม่เก็บซ้ำ
B4: แผ่นงาน | C4: ช่องกรอก / สิ่งที่เห็น | D4: ตาราง | E4: คอลัมน์ | F4: หมายเหตุ
B5: 1 ข้อมูลรายวิชา | C5: รหัสวิชา / ภาค / ปี / กลุ่มเรียน | D5: Course | E5: code, semester, year, section | F5: สี่ค่านี้รวมกันต้องไม่ซ้ำ
B6: 1 ข้อมูลรายวิชา | C6: เกณฑ์ผ่านรายวิชา | D6: Course | E6: passCriteria | F6: ใช้ตัดสินผ่าน/ไม่ผ่านรายบุคคล
B7: 1 ข้อมูลรายวิชา | C7: เป้าหมายระดับชั้น | D7: Course | E7: classTarget | F7: ใช้ตัดสินว่า CLO บรรลุหรือไม่
B8: 1 ข้อมูลรายวิชา | C8: อาจารย์ผู้รับผิดชอบ / ผู้สอนร่วม | D8: CourseInstructor | E8: userId, role | F8: LEAD ได้ไม่เกิน 1 คนต่อรายวิชา
B9: 2 CLO | C9: ผลลัพธ์การเรียนรู้ที่คาดหวัง | D9: CLO | E9: description
B10: 2 CLO | C10: เกณฑ์ผ่านของ CLO | D10: CLO | E10: threshold | F10: เกณฑ์รายบุคคล ไม่ใช่ระดับชั้น
B11: 2 CLO | C11: จุดประสงค์เชิงพฤติกรรม | D11: BehavioralObjective | E11: cloId, number, description | F11: ใช้ตามรอย ไม่กระทบคะแนน
B12: 2 CLO | C12: ระดับ Bloom | D12: CLO | E12: bloomLevel | F12: ผู้สอนเลือกเอง ไม่มีค่าเริ่มต้น
B13: 2 CLO | C13: เป้าหมายผู้ผ่านราย CLO | D13: CLO | E13: classTarget | F13: เว้นว่าง = ใช้ค่าของรายวิชา
B14: 3 แผนประเมิน มคอ.3 | C14: งาน/กิจกรรม และวิธีการประเมิน | D14: Activity | E14: name, method
B15: 3 แผนประเมิน มคอ.3 | C15: คะแนนเต็ม | D15: Activity | E15: maxScore | F15: ต้องมากกว่า 0
B16: 3 แผนประเมิน มคอ.3 | C16: สัดส่วนการประเมิน (%) | D16: Activity | E16: weight | F16: รวมทุกกิจกรรมต้องได้ 100
B17: 3 แผนประเมิน มคอ.3 | C17: สัปดาห์ที่ประเมิน | D17: — ยังไม่มีที่เก็บ — | E17: ต้องเพิ่มคอลัมน์ | F17: มคอ.3 ต้องระบุ แต่ฐานข้อมูลยังไม่รองรับ
B18: 4 เมทริกซ์ CLO x กิจกรรม | C18: ตัวเลขน้ำหนักในเมทริกซ์ | D18: AssessmentCriteria | E18: activityId, cloId, weight | F18: ช่องที่เป็น 0 ไม่สร้างแถว
B19: 4 เมทริกซ์ CLO x กิจกรรม | C19: น้ำหนักของ CLO | D19: — ไม่เก็บ — | E19: คำนวณจากเมทริกซ์ | F19: ป้องกันตัวเลขสองที่ไม่ตรงกัน
B20: 5 รายชื่อนักศึกษา | C20: รหัสนักศึกษา / ชื่อ | D20: Student | E20: studentCode, name, courseId | F20: ห้ามซ้ำภายในรายวิชาเดียวกัน
B21: 6 กรอกคะแนน | C21: ตัวเลขคะแนน | D21: Score | E21: studentId, activityId, score | F21: เว้นว่างไม่สร้างแถว · 0 สร้างแถว
B22: 6 กรอกคะแนน | C22: การอัปโหลดไฟล์ | D22: ScoreUploadLog | E22: fileName, recordsOk, recordsFail | F22: บันทึกทุกครั้งแม้ไฟล์ผิดทั้งไฟล์
B23: 7 ผลการบรรลุ CLO | C23: คะแนน CLO รายบุคคล | D23: — ไม่เก็บ — | E23: คำนวณสด | F23: อ่านจากคะแนนดิบและน้ำหนัก
B24: 7 ผลการบรรลุ CLO | C24: สถานะการติดตาม | D24: — ไม่เก็บ — | E24: คำนวณสด | F24: ยังไม่บรรลุ CLO อย่างน้อย 1 ข้อ
B25: 9 รายงาน มคอ.5 | C25: ตารางรายงาน มคอ.5 | D25: — ไม่เก็บ — | E25: คำนวณสด | F25: ส่งออกเป็นไฟล์ได้ตามข้อกำหนดของระบบ
B27: แถวสีเขียวคือค่าที่ระบบคำนวณให้ ไม่มีการเก็บซ้ำในฐานข้อมูล · แถวสีชมพูคือข้อมูลที่ มคอ. ต้องการแต่ฐานข้อมูลยังไม่รองรับ ซึ่งต้องตัดสินใจก่อนพัฒนาส่วนออกรายงาน
