Workbook

Sheet README
B2: CMAS — จากหน้าจอที่อาจารย์กรอก สู่ตารางในฐานข้อมูล
B3: ไฟล์เดียว 2 มุมมองของข้อมูลชุดเดียวกัน (ข้อมูลจำลอง) — เพื่อให้ทีมเห็นว่ากรอกอะไรแล้วลงตารางไหน
B5: แผนผังการไหลของข้อมูล
B6: หน้าจอ (UI) | C6: อาจารย์กรอกอะไร | D6: ลงตารางใดในฐานข้อมูล
B7: UI-1 รายวิชา | C7: ข้อมูลรายวิชา + เกณฑ์ผ่าน + เป้าหมายระดับชั้น | D7: Course (1 แถว)
B8: UI-2 CLO | C8: ผลลัพธ์การเรียนรู้ + จุดประสงค์เชิงพฤติกรรม | D8: CLO · BehavioralObjective
B9: UI-3 กิจกรรม | C9: กิจกรรมประเมิน + คะแนนเต็ม + น้ำหนักต่อวิชา | D9: Activity
B10: UI-4 Mapping | C10: เมทริกซ์น้ำหนัก กิจกรรม × CLO ← หัวใจของระบบ | D10: AssessmentCriteria · ObjectiveAssessment
B11: UI-5 รายชื่อ | C11: รายชื่อนักศึกษาในวิชา | D11: Student (= การลงทะเบียน ไม่ใช่ตัวคน)
B12: UI-6 กรอกคะแนน | C12: คะแนนรายคน รายกิจกรรม | D12: Score (มีแถวเฉพาะช่องที่กรอกแล้ว)
B13: UI-7 ผลลัพธ์ CLO | C13: ไม่ได้กรอก — ระบบคำนวณให้ | D13: ไม่มีตารางเก็บ! คำนวณสดทุกครั้งที่เปิดดู
B15: สิ่งที่ไฟล์นี้ตั้งใจให้เห็น
B16: น้ำหนักมี 2 ชั้น อย่าสับสน | C16: Activity.weight = กิจกรรมนี้คิดเป็นกี่ % ของคะแนนวิชา (รวมทุกกิจกรรม = 100) ส่วน AssessmentCriteria.weight = กิจกรรมนี้เอาไปวัด CLO ตัวไหนกี่ % (รวมต่อ 1 กิจกรรม = 100) ส่วน CLO ไม่มีน้ำหนักของตัวเอง เป็นค่าที่คำนวณออกมา (CR-02)
B17: ช่องว่าง ≠ ศูนย์ | C17: ช่องคะแนนที่เว้นว่าง = ยังไม่ประเมิน จะไม่มีแถวในตาราง Score เลย ส่วน 0 = สอบแล้วได้ 0 จริง มีแถวและถูกนำไปคำนวณ ดูนักศึกษา 65010007 (ได้ 0 จริง) เทียบกับ 65010008 (ยังไม่ประเมินเลย)
B18: ผลลัพธ์ไม่ถูกเก็บลงฐานข้อมูล | C18: คะแนน CLO / attainment / at-risk คำนวณสดจากตาราง Score + AssessmentCriteria ทุกครั้ง จึงไม่มีวันขัดแย้งกับคะแนนดิบ และการแก้คะแนนย้อนหลังจะสะท้อนผลทันที
B19: สูตรในไฟล์นี้ทำงานจริง | C19: ลองแก้คะแนนใน UI-6 กรอกคะแนน แล้วดู UI-7 ผลลัพธ์ CLO เปลี่ยนตาม — เป็นสูตร Excel จริง ที่เขียนตาม CR-02 ถึง CR-05 ใน SRS ไม่ใช่ตัวเลขที่พิมพ์ทิ้งไว้
B20: กิจกรรมที่ไม่ได้วัด CLO นั้น = ไม่มีแถว | C20: ช่อง 0 ในเมทริกซ์ UI-4 Mapping แปลว่าไม่มีความสัมพันธ์ ระบบจะไม่สร้างแถวใน AssessmentCriteria (ดูได้ว่าเมทริกซ์ 5×4 = 20 ช่อง แต่มีแถวจริงแค่ 10 แถว)
B22: ข้อมูลทั้งหมดในไฟล์นี้เป็นข้อมูลจำลองเพื่อการอธิบาย ไม่ใช่ข้อมูลจริงของนักศึกษา · โครงสร้างอ้างอิง database/schema.prisma (single-tenant, 11 ตาราง) และกฎการคำนวณ CR-01…CR-07 ใน SRS

Sheet UI-1 รายวิชา
A1: UI-1 · ตั้งค่ารายวิชา
A2: หน้าจอแรกที่อาจารย์กรอกเมื่อเปิดวิชาใหม่ → บันทึกเป็น 1 แถวในตาราง Course
B4: ช่องกรอกบนหน้าจอ | C4: ค่าที่กรอก (ตัวอย่าง) | D4: → ลงคอลัมน์ใดของตาราง Course
B5: รหัสวิชา | C5: 90641002 | D5: code
B6: ชื่อวิชา (ไทย) | C6: ระบบฐานข้อมูล | D6: name
B7: ชื่อวิชา (อังกฤษ) | C7: Database Systems | D7: nameEn
B8: ภาคการศึกษา | C8: 1 | D8: semester
B9: ปีการศึกษา (พ.ศ.) | C9: 2568 | D9: year
B10: กลุ่มเรียน (Section) | C10: 01 | D10: section
B11: หน่วยกิต (บรรยาย-ปฏิบัติ-ศึกษาเอง) | C11: 3 (2-2-5) | D11: credits, lectureHours, practiceHours, selfStudyHours
B12: รูปแบบการตัดเกรด | C12: LETTER | D12: gradingType
B13: เกณฑ์ผ่านรายวิชา (%) | C13: 60 | D13: passCriteria ← CR-05 ใช้ค่านี้
B14: เป้าหมายระดับชั้น / Class Target (%) | C14: 70 | D14: classTarget ← CR-04 ใช้ค่านี้
B16: passCriteria และ classTarget เก็บ 'ราย Course' ไม่ใช่ค่ากลางของระบบ — เพื่อไม่ให้การแก้ค่ากลาง วันนี้ ย้อนไปเปลี่ยนผลว่า 'CLO บรรลุ/ไม่บรรลุ' ของเทอมที่แล้วโดยไม่มีใครรู้ (OI-03)

Sheet UI-2 CLO
A1: UI-2 · กำหนด CLO และจุดประสงค์เชิงพฤติกรรม
A2: CLO ไม่มีช่อง 'น้ำหนัก' ให้กรอก — น้ำหนักของ CLO เป็นค่าที่คำนวณจากเมทริกซ์ใน UI-4 (CR-02)
A4: ลำดับ | B4: cloId (ระบบสร้าง) | C4: CLO ที่ | D4: คำอธิบายผลลัพธ์การเรียนรู้ | E4: เกณฑ์ผ่าน (%) | F4: → ตาราง CLO
A5: 1 | B5: clo-01 | C5: 1 | D5: ออกแบบฐานข้อมูลเชิงสัมพันธ์จากโจทย์ที่กำหนดได้ | E5: 60 | F5: threshold
A6: 2 | B6: clo-02 | C6: 2 | D6: เขียนคำสั่ง SQL เพื่อสืบค้นและจัดการข้อมูลได้ | E6: 60
A7: 3 | B7: clo-03 | C7: 3 | D7: ทำ Normalization ถึงระดับ 3NF ได้ถูกต้อง | E7: 65
A8: 4 | B8: clo-04 | C8: 4 | D8: ทำงานเป็นทีมและนำเสนอผลงานได้ | E8: 60
A10: เกณฑ์ผ่าน (threshold) คือเกณฑ์ราย 'นักศึกษา 1 คน' ต่อ CLO 1 ข้อ — คนละตัวกับ Class Target ที่เป็นเกณฑ์ระดับชั้นเรียนใน UI-1
A12: จุดประสงค์เชิงพฤติกรรม (ย่อยจาก CLO)
A13: ลำดับ | B13: objectiveId | C13: สังกัด CLO | D13: ข้อที่ | E13: คำอธิบาย | F13: → ตาราง BehavioralObjective
A14: 1 | B14: obj-01 | C14: CLO 1 | D14: 1 | E14: เขียน ER-Diagram จากความต้องการของผู้ใช้ได้ | F14: cloId, number, description
A15: 2 | B15: obj-02 | C15: CLO 1 | D15: 2 | E15: แปลง ER-Diagram เป็นตารางเชิงสัมพันธ์ได้
A16: 3 | B16: obj-03 | C16: CLO 2 | D16: 1 | E16: เขียนคำสั่ง SELECT พร้อม JOIN หลายตารางได้
A17: 4 | B17: obj-04 | C17: CLO 2 | D17: 2 | E17: ใช้ subquery และฟังก์ชันรวม (aggregate) ได้
A18: 5 | B18: obj-05 | C18: CLO 3 | D18: 1 | E18: ระบุ functional dependency ของตารางได้
A19: 6 | B19: obj-06 | C19: CLO 3 | D19: 2 | E19: แปลงตารางให้อยู่ในรูป 3NF ได้
A20: 7 | B20: obj-07 | C20: CLO 4 | D20: 1 | E20: นำเสนอผลงานกลุ่มต่อชั้นเรียนได้
A22: จุดประสงค์เชิงพฤติกรรมใช้เพื่อการตามรอย (traceability) เท่านั้น ไม่มีผลต่อคะแนน CLO ที่คำนวณได้ (FR-35)

Sheet UI-3 กิจกรรม
A1: UI-3 · กิจกรรมการประเมิน
A2: น้ำหนักในหน้านี้คือ 'กิจกรรมนี้คิดเป็นกี่ % ของคะแนนรวมวิชา' — รวมทุกกิจกรรมต้องได้ 100 พอดี (CR-01)
A4: ลำดับ | B4: activityId | C4: ชื่อกิจกรรม | D4: วิธีประเมิน | E4: คะแนนเต็ม | F4: น้ำหนักต่อวิชา (%) | G4: → ตาราง Activity
A5: 1 | B5: act-01 | C5: Quiz 1 — ER Diagram | D5: สอบย่อย | E5: 20 | F5: 10 | G5: maxScore, weight
A6: 2 | B6: act-02 | C6: สอบกลางภาค | D6: สอบข้อเขียน | E6: 100 | F6: 30
A7: 3 | B7: act-03 | C7: ปฏิบัติการ SQL (Lab) | D7: ประเมินชิ้นงาน | E7: 50 | F7: 20
A8: 4 | B8: act-04 | C8: โปรเจกต์กลุ่ม | D8: ประเมินชิ้นงาน + นำเสนอ | E8: 100 | F8: 25
A9: 5 | B9: act-05 | C9: สอบปลายภาค | D9: สอบข้อเขียน | E9: 100 | F9: 15
C10: รวมน้ำหนักทุกกิจกรรม | F10: =SUM(F5:F9) | G10: =IF(F10=100,"ถูกต้อง — ครบ 100","ผิดกฎ CR-01 — ต้องได้ 100")
A12: คะแนนเต็ม (maxScore) ต้องมากกว่า 0 เสมอ เพราะทุกสูตรคำนวณ CLO ต้องเอาคะแนนหารด้วยค่านี้ — ฐานข้อมูลบังคับด้วย CHECK constraint (DC-03)

Sheet UI-4 Mapping
A1: UI-4 · เมทริกซ์น้ำหนัก กิจกรรม × CLO
A2: กรอกว่า 'กิจกรรมนี้ เอาไปวัด CLO ตัวไหน กี่ %' — แต่ละแถวต้องรวมได้ 100 · ช่อง 0 = ไม่ได้วัด CLO นั้น จะไม่มีแถวในตาราง AssessmentCriteria
A4: ลำดับ | B4: กิจกรรม \ CLO | C4: CLO 1 | D4: CLO 2 | E4: CLO 3 | F4: CLO 4 | G4: รวมแถว | H4: สถานะ (ต้องรวม = 100)
A5: 1 | B5: Quiz 1 — ER Diagram | C5: 100 | D5: 0 | E5: 0 | F5: 0 | G5: =SUM(C5:F5) | H5: =IF(G5=100,"ครบ 100","ผิด — ได้ "&G5)
A6: 2 | B6: สอบกลางภาค | C6: 40 | D6: 60 | E6: 0 | F6: 0 | G6: =SUM(C6:F6) | H6: =IF(G6=100,"ครบ 100","ผิด — ได้ "&G6)
A7: 3 | B7: ปฏิบัติการ SQL (Lab) | C7: 0 | D7: 70 | E7: 30 | F7: 0 | G7: =SUM(C7:F7) | H7: =IF(G7=100,"ครบ 100","ผิด — ได้ "&G7)
A8: 4 | B8: โปรเจกต์กลุ่ม | C8: 20 | D8: 0 | E8: 40 | F8: 40 | G8: =SUM(C8:F8) | H8: =IF(G8=100,"ครบ 100","ผิด — ได้ "&G8)
A9: 5 | B9: สอบปลายภาค | C9: 0 | D9: 50 | E9: 50 | F9: 0 | G9: =SUM(C9:F9) | H9: =IF(G9=100,"ครบ 100","ผิด — ได้ "&G9)
B11: น้ำหนักของ CLO (CR-02) % | C11: =SUMPRODUCT('UI-3 กิจกรรม'!$F$5:$F$9,C5:C9)/100 | D11: =SUMPRODUCT('UI-3 กิจกรรม'!$F$5:$F$9,D5:D9)/100 | E11: =SUMPRODUCT('UI-3 กิจกรรม'!$F$5:$F$9,E5:E9)/100 | F11: =SUMPRODUCT('UI-3 กิจกรรม'!$F$5:$F$9,F5:F9)/100 | G11: =SUM(C11:F11) | H11: รวมต้องได้ 100 อัตโนมัติ
A13: แถวสีเขียวคือค่าที่ 'คำนวณได้' ไม่ใช่ค่าที่กรอก — CLO ไม่มีคอลัมน์ weight ในฐานข้อมูล ถ้าเก็บไว้ซ้ำจะมีวันที่ค่าสองที่ไม่ตรงกัน (OI-02)
A15: เมทริกซ์ 5×4 = 20 ช่อง แต่มีแถวจริงในตาราง AssessmentCriteria เพียง 10 แถว (เฉพาะช่องที่ > 0)

Sheet UI-5 รายชื่อ
A1: UI-5 · รายชื่อนักศึกษาในรายวิชา
A2: 1 แถว = 1 การลงทะเบียน ไม่ใช่ 1 คน — คนเดียวกันลงเรียน 3 วิชา จะมี 3 แถว ชื่อซ้ำกันโดยตั้งใจ
A4: ลำดับ | B4: studentId | C4: รหัสนักศึกษา | D4: ชื่อ-นามสกุล | E4: → ตาราง Student
A5: 1 | B5: std-01 | C5: 65010001 | D5: นายกิตติพงษ์ แสงทอง | E5: studentCode, name, courseId
A6: 2 | B6: std-02 | C6: 65010002 | D6: นางสาวจิราพร มีสุข
A7: 3 | B7: std-03 | C7: 65010003 | D7: นายธนกร ศรีสุข
A8: 4 | B8: std-04 | C8: 65010004 | D8: นางสาวปาริชาติ วงศ์ดี
A9: 5 | B9: std-05 | C9: 65010005 | D9: นายภานุวัฒน์ ทองสุข
A10: 6 | B10: std-06 | C10: 65010006 | D10: นางสาวรัตนาภรณ์ ใจงาม
A11: 7 | B11: std-07 | C11: 65010007 | D11: นายวรวุฒิ ชัยมงคล
A12: 8 | B12: std-08 | C12: 65010008 | D12: นางสาวศิริพร แก้วมณี
A14: รหัสนักศึกษาห้ามซ้ำ 'ภายในวิชาเดียวกัน' (FR-51) แต่ซ้ำข้ามวิชาได้ เพราะนั่นคือคนเดิมลงเรียนอีกวิชา

Sheet UI-6 กรอกคะแนน
A1: UI-6 · กรอกคะแนนรายกิจกรรม
A2: คอลัมน์เป็น 'กิจกรรม' ไม่ใช่ CLO (FR-60) — เว้นว่าง = ยังไม่ประเมิน · 0 = ได้ 0 คะแนนจริง
A4: ลำดับ | B4: รหัสนักศึกษา | C4: ชื่อ-นามสกุล | D4: ='UI-3 กิจกรรม'!C5&" (เต็ม "&'UI-3 กิจกรรม'!E5&")" | E4: ='UI-3 กิจกรรม'!C6&" (เต็ม "&'UI-3 กิจกรรม'!E6&")" | F4: ='UI-3 กิจกรรม'!C7&" (เต็ม "&'UI-3 กิจกรรม'!E7&")" | G4: ='UI-3 กิจกรรม'!C8&" (เต็ม "&'UI-3 กิจกรรม'!E8&")" | H4: ='UI-3 กิจกรรม'!C9&" (เต็ม "&'UI-3 กิจกรรม'!E9&")" | I4: → ตาราง Score
A5: 1 | B5: 65010001 | C5: นายกิตติพงษ์ แสงทอง | D5: 18 | E5: 85 | F5: 45 | G5: 88 | H5: 82 | I5: 5 แถว — ครบทุกกิจกรรม
A6: 2 | B6: 65010002 | C6: นางสาวจิราพร มีสุข | D6: 15 | E6: 70 | F6: 38 | G6: 75 | H6: 68 | I6: 5 แถว — ครบทุกกิจกรรม
A7: 3 | B7: 65010003 | C7: นายธนกร ศรีสุข | D7: 12 | E7: 55 | F7: 30 | G7: 62 | H7: 58 | I7: 5 แถว — ครบทุกกิจกรรม
A8: 4 | B8: 65010004 | C8: นางสาวปาริชาติ วงศ์ดี | D8: 8 | E8: 42 | F8: 22 | G8: 55 | H8: 40 | I8: 5 แถว — ครบทุกกิจกรรม
A9: 5 | B9: 65010005 | C9: นายภานุวัฒน์ ทองสุข | D9: 20 | E9: 92 | F9: 48 | G9: 95 | H9: 90 | I9: 5 แถว — ครบทุกกิจกรรม
A10: 6 | B10: 65010006 | C10: นางสาวรัตนาภรณ์ ใจงาม | D10: 14 | E10: 65 | G10: 70 | H10: 60 | I10: 4 แถว — ยังไม่ประเมิน 1 กิจกรรม
A11: 7 | B11: 65010007 | C11: นายวรวุฒิ ชัยมงคล | D11: 0 | E11: 38 | F11: 20 | G11: 50 | H11: 35 | I11: 5 แถว — ครบทุกกิจกรรม
A12: 8 | B12: 65010008 | C12: นางสาวศิริพร แก้วมณี | I12: 0 แถว — ยังไม่ประเมิน 5 กิจกรรม
A14: กรอกไป 34 ช่อง จากทั้งหมด 40 ช่อง → ตาราง Score จึงมี 34 แถว ไม่ใช่ 40 แถว เพราะช่องว่างไม่สร้างแถว (FR-62)
A15: ลองแก้ตัวเลขในหน้านี้ แล้วเปิดหน้า UI-7 ผลลัพธ์ CLO — คะแนน CLO และผลการบรรลุจะเปลี่ยนตามทันที

Sheet UI-7 ผลลัพธ์ CLO
A1: UI-7 · ผลลัพธ์การบรรลุ CLO (ระบบคำนวณให้ ไม่มีการกรอก)
A2: ทุกตัวเลขในหน้านี้ 'ไม่ถูกเก็บลงฐานข้อมูล' — คำนวณสดจากตาราง Score + AssessmentCriteria ทุกครั้ง · สูตรตาม CR-02 ถึง CR-05 ใน SRS
A4: ขั้นที่ 1 — สัดส่วนคะแนนที่ได้ (score ÷ maxScore) · ช่องที่ยังไม่ประเมินให้เป็น 0
A5: ลำดับ | B5: รหัส | C5: ชื่อ-นามสกุล | D5: Quiz 1 — ER Diagram | E5: สอบกลางภาค | F5: ปฏิบัติการ SQL (Lab) | G5: โปรเจกต์กลุ่ม | H5: สอบปลายภาค
A6: 1 | B6: 65010001 | C6: นายกิตติพงษ์ แสงทอง | D6: =IF('UI-6 กรอกคะแนน'!D5="",0,'UI-6 กรอกคะแนน'!D5/'UI-3 กิจกรรม'!$E$5) | E6: =IF('UI-6 กรอกคะแนน'!E5="",0,'UI-6 กรอกคะแนน'!E5/'UI-3 กิจกรรม'!$E$6) | F6: =IF('UI-6 กรอกคะแนน'!F5="",0,'UI-6 กรอกคะแนน'!F5/'UI-3 กิจกรรม'!$E$7) | G6: =IF('UI-6 กรอกคะแนน'!G5="",0,'UI-6 กรอกคะแนน'!G5/'UI-3 กิจกรรม'!$E$8) | H6: =IF('UI-6 กรอกคะแนน'!H5="",0,'UI-6 กรอกคะแนน'!H5/'UI-3 กิจกรรม'!$E$9)
A7: 2 | B7: 65010002 | C7: นางสาวจิราพร มีสุข | D7: =IF('UI-6 กรอกคะแนน'!D6="",0,'UI-6 กรอกคะแนน'!D6/'UI-3 กิจกรรม'!$E$5) | E7: =IF('UI-6 กรอกคะแนน'!E6="",0,'UI-6 กรอกคะแนน'!E6/'UI-3 กิจกรรม'!$E$6) | F7: =IF('UI-6 กรอกคะแนน'!F6="",0,'UI-6 กรอกคะแนน'!F6/'UI-3 กิจกรรม'!$E$7) | G7: =IF('UI-6 กรอกคะแนน'!G6="",0,'UI-6 กรอกคะแนน'!G6/'UI-3 กิจกรรม'!$E$8) | H7: =IF('UI-6 กรอกคะแนน'!H6="",0,'UI-6 กรอกคะแนน'!H6/'UI-3 กิจกรรม'!$E$9)
A8: 3 | B8: 65010003 | C8: นายธนกร ศรีสุข | D8: =IF('UI-6 กรอกคะแนน'!D7="",0,'UI-6 กรอกคะแนน'!D7/'UI-3 กิจกรรม'!$E$5) | E8: =IF('UI-6 กรอกคะแนน'!E7="",0,'UI-6 กรอกคะแนน'!E7/'UI-3 กิจกรรม'!$E$6) | F8: =IF('UI-6 กรอกคะแนน'!F7="",0,'UI-6 กรอกคะแนน'!F7/'UI-3 กิจกรรม'!$E$7) | G8: =IF('UI-6 กรอกคะแนน'!G7="",0,'UI-6 กรอกคะแนน'!G7/'UI-3 กิจกรรม'!$E$8) | H8: =IF('UI-6 กรอกคะแนน'!H7="",0,'UI-6 กรอกคะแนน'!H7/'UI-3 กิจกรรม'!$E$9)
A9: 4 | B9: 65010004 | C9: นางสาวปาริชาติ วงศ์ดี | D9: =IF('UI-6 กรอกคะแนน'!D8="",0,'UI-6 กรอกคะแนน'!D8/'UI-3 กิจกรรม'!$E$5) | E9: =IF('UI-6 กรอกคะแนน'!E8="",0,'UI-6 กรอกคะแนน'!E8/'UI-3 กิจกรรม'!$E$6) | F9: =IF('UI-6 กรอกคะแนน'!F8="",0,'UI-6 กรอกคะแนน'!F8/'UI-3 กิจกรรม'!$E$7) | G9: =IF('UI-6 กรอกคะแนน'!G8="",0,'UI-6 กรอกคะแนน'!G8/'UI-3 กิจกรรม'!$E$8) | H9: =IF('UI-6 กรอกคะแนน'!H8="",0,'UI-6 กรอกคะแนน'!H8/'UI-3 กิจกรรม'!$E$9)
A10: 5 | B10: 65010005 | C10: นายภานุวัฒน์ ทองสุข | D10: =IF('UI-6 กรอกคะแนน'!D9="",0,'UI-6 กรอกคะแนน'!D9/'UI-3 กิจกรรม'!$E$5) | E10: =IF('UI-6 กรอกคะแนน'!E9="",0,'UI-6 กรอกคะแนน'!E9/'UI-3 กิจกรรม'!$E$6) | F10: =IF('UI-6 กรอกคะแนน'!F9="",0,'UI-6 กรอกคะแนน'!F9/'UI-3 กิจกรรม'!$E$7) | G10: =IF('UI-6 กรอกคะแนน'!G9="",0,'UI-6 กรอกคะแนน'!G9/'UI-3 กิจกรรม'!$E$8) | H10: =IF('UI-6 กรอกคะแนน'!H9="",0,'UI-6 กรอกคะแนน'!H9/'UI-3 กิจกรรม'!$E$9)
A11: 6 | B11: 65010006 | C11: นางสาวรัตนาภรณ์ ใจงาม | D11: =IF('UI-6 กรอกคะแนน'!D10="",0,'UI-6 กรอกคะแนน'!D10/'UI-3 กิจกรรม'!$E$5) | E11: =IF('UI-6 กรอกคะแนน'!E10="",0,'UI-6 กรอกคะแนน'!E10/'UI-3 กิจกรรม'!$E$6) | F11: =IF('UI-6 กรอกคะแนน'!F10="",0,'UI-6 กรอกคะแนน'!F10/'UI-3 กิจกรรม'!$E$7) | G11: =IF('UI-6 กรอกคะแนน'!G10="",0,'UI-6 กรอกคะแนน'!G10/'UI-3 กิจกรรม'!$E$8) | H11: =IF('UI-6 กรอกคะแนน'!H10="",0,'UI-6 กรอกคะแนน'!H10/'UI-3 กิจกรรม'!$E$9)
A12: 7 | B12: 65010007 | C12: นายวรวุฒิ ชัยมงคล | D12: =IF('UI-6 กรอกคะแนน'!D11="",0,'UI-6 กรอกคะแนน'!D11/'UI-3 กิจกรรม'!$E$5) | E12: =IF('UI-6 กรอกคะแนน'!E11="",0,'UI-6 กรอกคะแนน'!E11/'UI-3 กิจกรรม'!$E$6) | F12: =IF('UI-6 กรอกคะแนน'!F11="",0,'UI-6 กรอกคะแนน'!F11/'UI-3 กิจกรรม'!$E$7) | G12: =IF('UI-6 กรอกคะแนน'!G11="",0,'UI-6 กรอกคะแนน'!G11/'UI-3 กิจกรรม'!$E$8) | H12: =IF('UI-6 กรอกคะแนน'!H11="",0,'UI-6 กรอกคะแนน'!H11/'UI-3 กิจกรรม'!$E$9)
A13: 8 | B13: 65010008 | C13: นางสาวศิริพร แก้วมณี | D13: =IF('UI-6 กรอกคะแนน'!D12="",0,'UI-6 กรอกคะแนน'!D12/'UI-3 กิจกรรม'!$E$5) | E13: =IF('UI-6 กรอกคะแนน'!E12="",0,'UI-6 กรอกคะแนน'!E12/'UI-3 กิจกรรม'!$E$6) | F13: =IF('UI-6 กรอกคะแนน'!F12="",0,'UI-6 กรอกคะแนน'!F12/'UI-3 กิจกรรม'!$E$7) | G13: =IF('UI-6 กรอกคะแนน'!G12="",0,'UI-6 กรอกคะแนน'!G12/'UI-3 กิจกรรม'!$E$8) | H13: =IF('UI-6 กรอกคะแนน'!H12="",0,'UI-6 กรอกคะแนน'!H12/'UI-3 กิจกรรม'!$E$9)
A15: ขั้นที่ 2 — มีคะแนนแล้วหรือยัง (1 = ประเมินแล้ว, 0 = ยังไม่ประเมิน) · ตัวนี้คือสิ่งที่แยก "ว่าง" ออกจาก "ศูนย์"
A16: ลำดับ | B16: รหัส | C16: ชื่อ-นามสกุล | D16: Quiz 1 — ER Diagram | E16: สอบกลางภาค | F16: ปฏิบัติการ SQL (Lab) | G16: โปรเจกต์กลุ่ม | H16: สอบปลายภาค
A17: 1 | B17: 65010001 | C17: นายกิตติพงษ์ แสงทอง | D17: =IF('UI-6 กรอกคะแนน'!D5="",0,1) | E17: =IF('UI-6 กรอกคะแนน'!E5="",0,1) | F17: =IF('UI-6 กรอกคะแนน'!F5="",0,1) | G17: =IF('UI-6 กรอกคะแนน'!G5="",0,1) | H17: =IF('UI-6 กรอกคะแนน'!H5="",0,1)
A18: 2 | B18: 65010002 | C18: นางสาวจิราพร มีสุข | D18: =IF('UI-6 กรอกคะแนน'!D6="",0,1) | E18: =IF('UI-6 กรอกคะแนน'!E6="",0,1) | F18: =IF('UI-6 กรอกคะแนน'!F6="",0,1) | G18: =IF('UI-6 กรอกคะแนน'!G6="",0,1) | H18: =IF('UI-6 กรอกคะแนน'!H6="",0,1)
A19: 3 | B19: 65010003 | C19: นายธนกร ศรีสุข | D19: =IF('UI-6 กรอกคะแนน'!D7="",0,1) | E19: =IF('UI-6 กรอกคะแนน'!E7="",0,1) | F19: =IF('UI-6 กรอกคะแนน'!F7="",0,1) | G19: =IF('UI-6 กรอกคะแนน'!G7="",0,1) | H19: =IF('UI-6 กรอกคะแนน'!H7="",0,1)
A20: 4 | B20: 65010004 | C20: นางสาวปาริชาติ วงศ์ดี | D20: =IF('UI-6 กรอกคะแนน'!D8="",0,1) | E20: =IF('UI-6 กรอกคะแนน'!E8="",0,1) | F20: =IF('UI-6 กรอกคะแนน'!F8="",0,1) | G20: =IF('UI-6 กรอกคะแนน'!G8="",0,1) | H20: =IF('UI-6 กรอกคะแนน'!H8="",0,1)
A21: 5 | B21: 65010005 | C21: นายภานุวัฒน์ ทองสุข | D21: =IF('UI-6 กรอกคะแนน'!D9="",0,1) | E21: =IF('UI-6 กรอกคะแนน'!E9="",0,1) | F21: =IF('UI-6 กรอกคะแนน'!F9="",0,1) | G21: =IF('UI-6 กรอกคะแนน'!G9="",0,1) | H21: =IF('UI-6 กรอกคะแนน'!H9="",0,1)
A22: 6 | B22: 65010006 | C22: นางสาวรัตนาภรณ์ ใจงาม | D22: =IF('UI-6 กรอกคะแนน'!D10="",0,1) | E22: =IF('UI-6 กรอกคะแนน'!E10="",0,1) | F22: =IF('UI-6 กรอกคะแนน'!F10="",0,1) | G22: =IF('UI-6 กรอกคะแนน'!G10="",0,1) | H22: =IF('UI-6 กรอกคะแนน'!H10="",0,1)
A23: 7 | B23: 65010007 | C23: นายวรวุฒิ ชัยมงคล | D23: =IF('UI-6 กรอกคะแนน'!D11="",0,1) | E23: =IF('UI-6 กรอกคะแนน'!E11="",0,1) | F23: =IF('UI-6 กรอกคะแนน'!F11="",0,1) | G23: =IF('UI-6 กรอกคะแนน'!G11="",0,1) | H23: =IF('UI-6 กรอกคะแนน'!H11="",0,1)
A24: 8 | B24: 65010008 | C24: นางสาวศิริพร แก้วมณี | D24: =IF('UI-6 กรอกคะแนน'!D12="",0,1) | E24: =IF('UI-6 กรอกคะแนน'!E12="",0,1) | F24: =IF('UI-6 กรอกคะแนน'!F12="",0,1) | G24: =IF('UI-6 กรอกคะแนน'!G12="",0,1) | H24: =IF('UI-6 กรอกคะแนน'!H12="",0,1)
A26: ขั้นที่ 3 — ตารางน้ำหนักที่สลับแกนจาก UI-4 (เพื่อให้คูณกับแถวคะแนนได้)
C27: CLO \ กิจกรรม | D27: Quiz 1 — ER Diagram | E27: สอบกลางภาค | F27: ปฏิบัติการ SQL (Lab) | G27: โปรเจกต์กลุ่ม | H27: สอบปลายภาค
C28: CLO 1 | D28: ='UI-4 Mapping'!C5 | E28: ='UI-4 Mapping'!C6 | F28: ='UI-4 Mapping'!C7 | G28: ='UI-4 Mapping'!C8 | H28: ='UI-4 Mapping'!C9
C29: CLO 2 | D29: ='UI-4 Mapping'!D5 | E29: ='UI-4 Mapping'!D6 | F29: ='UI-4 Mapping'!D7 | G29: ='UI-4 Mapping'!D8 | H29: ='UI-4 Mapping'!D9
C30: CLO 3 | D30: ='UI-4 Mapping'!E5 | E30: ='UI-4 Mapping'!E6 | F30: ='UI-4 Mapping'!E7 | G30: ='UI-4 Mapping'!E8 | H30: ='UI-4 Mapping'!E9
C31: CLO 4 | D31: ='UI-4 Mapping'!F5 | E31: ='UI-4 Mapping'!F6 | F31: ='UI-4 Mapping'!F7 | G31: ='UI-4 Mapping'!F8 | H31: ='UI-4 Mapping'!F9
C32: น้ำหนักกิจกรรมต่อวิชา (Aw) | D32: ='UI-3 กิจกรรม'!$F$5 | E32: ='UI-3 กิจกรรม'!$F$6 | F32: ='UI-3 กิจกรรม'!$F$7 | G32: ='UI-3 กิจกรรม'!$F$8 | H32: ='UI-3 กิจกรรม'!$F$9
C33: เกณฑ์ผ่านของแต่ละ CLO (threshold) | D33: ='UI-2 CLO'!$E$5 | E33: ='UI-2 CLO'!$E$6 | F33: ='UI-2 CLO'!$E$7 | G33: ='UI-2 CLO'!$E$8
A35: ขั้นที่ 4 — คะแนน CLO รายบุคคล (CR-03) · คะแนนรวมและสถานะ (CR-05)
A36: ลำดับ | B36: รหัส | C36: ชื่อ-นามสกุล | D36: CLO 1 (%) | E36: CLO 2 (%) | F36: CLO 3 (%) | G36: CLO 4 (%) | H36: คะแนนรวม (%) | I36: เพดาน ณ ตอนนี้ (%) | J36: กรอกแล้ว | K36: ผ่านวิชา? | L36: สถานะการติดตาม
A37: 1 | B37: 65010001 | C37: นายกิตติพงษ์ แสงทอง | D37: =IF(SUMPRODUCT($D$17:$H$17,$D$28:$H$28)=0,"—",SUMPRODUCT($D$6:$H$6,$D$28:$H$28)/SUMPRODUCT($D$17:$H$17,$D$28:$H$28)*100) | E37: =IF(SUMPRODUCT($D$17:$H$17,$D$29:$H$29)=0,"—",SUMPRODUCT($D$6:$H$6,$D$29:$H$29)/SUMPRODUCT($D$17:$H$17,$D$29:$H$29)*100) | F37: =IF(SUMPRODUCT($D$17:$H$17,$D$30:$H$30)=0,"—",SUMPRODUCT($D$6:$H$6,$D$30:$H$30)/SUMPRODUCT($D$17:$H$17,$D$30:$H$30)*100) | G37: =IF(SUMPRODUCT($D$17:$H$17,$D$31:$H$31)=0,"—",SUMPRODUCT($D$6:$H$6,$D$31:$H$31)/SUMPRODUCT($D$17:$H$17,$D$31:$H$31)*100) | H37: =SUMPRODUCT($D$6:$H$6,$D$32:$H$32) | I37: =SUMPRODUCT($D$17:$H$17,$D$32:$H$32) | J37: =COUNT('UI-6 กรอกคะแนน'!D5:H5)&"/5" | K37: =IF(COUNT($D37:$G37)=0,"—",IF($I37<100,"ยังตัดสินไม่ได้",IF($H37>='UI-1 รายวิชา'!$C$13,"ผ่าน","ไม่ผ่าน"))) | L37: =IF(COUNT($D37:$G37)=0,"ยังประเมินไม่ครบ",IF(SUMPRODUCT(--ISNUMBER($D37:$G37),--($D37:$G37<$D$33:$G$33))>0,"เสี่ยง (at-risk)","ปกติ"))
A38: 2 | B38: 65010002 | C38: นางสาวจิราพร มีสุข | D38: =IF(SUMPRODUCT($D$18:$H$18,$D$28:$H$28)=0,"—",SUMPRODUCT($D$7:$H$7,$D$28:$H$28)/SUMPRODUCT($D$18:$H$18,$D$28:$H$28)*100) | E38: =IF(SUMPRODUCT($D$18:$H$18,$D$29:$H$29)=0,"—",SUMPRODUCT($D$7:$H$7,$D$29:$H$29)/SUMPRODUCT($D$18:$H$18,$D$29:$H$29)*100) | F38: =IF(SUMPRODUCT($D$18:$H$18,$D$30:$H$30)=0,"—",SUMPRODUCT($D$7:$H$7,$D$30:$H$30)/SUMPRODUCT($D$18:$H$18,$D$30:$H$30)*100) | G38: =IF(SUMPRODUCT($D$18:$H$18,$D$31:$H$31)=0,"—",SUMPRODUCT($D$7:$H$7,$D$31:$H$31)/SUMPRODUCT($D$18:$H$18,$D$31:$H$31)*100) | H38: =SUMPRODUCT($D$7:$H$7,$D$32:$H$32) | I38: =SUMPRODUCT($D$18:$H$18,$D$32:$H$32) | J38: =COUNT('UI-6 กรอกคะแนน'!D6:H6)&"/5" | K38: =IF(COUNT($D38:$G38)=0,"—",IF($I38<100,"ยังตัดสินไม่ได้",IF($H38>='UI-1 รายวิชา'!$C$13,"ผ่าน","ไม่ผ่าน"))) | L38: =IF(COUNT($D38:$G38)=0,"ยังประเมินไม่ครบ",IF(SUMPRODUCT(--ISNUMBER($D38:$G38),--($D38:$G38<$D$33:$G$33))>0,"เสี่ยง (at-risk)","ปกติ"))
A39: 3 | B39: 65010003 | C39: นายธนกร ศรีสุข | D39: =IF(SUMPRODUCT($D$19:$H$19,$D$28:$H$28)=0,"—",SUMPRODUCT($D$8:$H$8,$D$28:$H$28)/SUMPRODUCT($D$19:$H$19,$D$28:$H$28)*100) | E39: =IF(SUMPRODUCT($D$19:$H$19,$D$29:$H$29)=0,"—",SUMPRODUCT($D$8:$H$8,$D$29:$H$29)/SUMPRODUCT($D$19:$H$19,$D$29:$H$29)*100) | F39: =IF(SUMPRODUCT($D$19:$H$19,$D$30:$H$30)=0,"—",SUMPRODUCT($D$8:$H$8,$D$30:$H$30)/SUMPRODUCT($D$19:$H$19,$D$30:$H$30)*100) | G39: =IF(SUMPRODUCT($D$19:$H$19,$D$31:$H$31)=0,"—",SUMPRODUCT($D$8:$H$8,$D$31:$H$31)/SUMPRODUCT($D$19:$H$19,$D$31:$H$31)*100) | H39: =SUMPRODUCT($D$8:$H$8,$D$32:$H$32) | I39: =SUMPRODUCT($D$19:$H$19,$D$32:$H$32) | J39: =COUNT('UI-6 กรอกคะแนน'!D7:H7)&"/5" | K39: =IF(COUNT($D39:$G39)=0,"—",IF($I39<100,"ยังตัดสินไม่ได้",IF($H39>='UI-1 รายวิชา'!$C$13,"ผ่าน","ไม่ผ่าน"))) | L39: =IF(COUNT($D39:$G39)=0,"ยังประเมินไม่ครบ",IF(SUMPRODUCT(--ISNUMBER($D39:$G39),--($D39:$G39<$D$33:$G$33))>0,"เสี่ยง (at-risk)","ปกติ"))
A40: 4 | B40: 65010004 | C40: นางสาวปาริชาติ วงศ์ดี | D40: =IF(SUMPRODUCT($D$20:$H$20,$D$28:$H$28)=0,"—",SUMPRODUCT($D$9:$H$9,$D$28:$H$28)/SUMPRODUCT($D$20:$H$20,$D$28:$H$28)*100) | E40: =IF(SUMPRODUCT($D$20:$H$20,$D$29:$H$29)=0,"—",SUMPRODUCT($D$9:$H$9,$D$29:$H$29)/SUMPRODUCT($D$20:$H$20,$D$29:$H$29)*100) | F40: =IF(SUMPRODUCT($D$20:$H$20,$D$30:$H$30)=0,"—",SUMPRODUCT($D$9:$H$9,$D$30:$H$30)/SUMPRODUCT($D$20:$H$20,$D$30:$H$30)*100) | G40: =IF(SUMPRODUCT($D$20:$H$20,$D$31:$H$31)=0,"—",SUMPRODUCT($D$9:$H$9,$D$31:$H$31)/SUMPRODUCT($D$20:$H$20,$D$31:$H$31)*100) | H40: =SUMPRODUCT($D$9:$H$9,$D$32:$H$32) | I40: =SUMPRODUCT($D$20:$H$20,$D$32:$H$32) | J40: =COUNT('UI-6 กรอกคะแนน'!D8:H8)&"/5" | K40: =IF(COUNT($D40:$G40)=0,"—",IF($I40<100,"ยังตัดสินไม่ได้",IF($H40>='UI-1 รายวิชา'!$C$13,"ผ่าน","ไม่ผ่าน"))) | L40: =IF(COUNT($D40:$G40)=0,"ยังประเมินไม่ครบ",IF(SUMPRODUCT(--ISNUMBER($D40:$G40),--($D40:$G40<$D$33:$G$33))>0,"เสี่ยง (at-risk)","ปกติ"))
A41: 5 | B41: 65010005 | C41: นายภานุวัฒน์ ทองสุข | D41: =IF(SUMPRODUCT($D$21:$H$21,$D$28:$H$28)=0,"—",SUMPRODUCT($D$10:$H$10,$D$28:$H$28)/SUMPRODUCT($D$21:$H$21,$D$28:$H$28)*100) | E41: =IF(SUMPRODUCT($D$21:$H$21,$D$29:$H$29)=0,"—",SUMPRODUCT($D$10:$H$10,$D$29:$H$29)/SUMPRODUCT($D$21:$H$21,$D$29:$H$29)*100) | F41: =IF(SUMPRODUCT($D$21:$H$21,$D$30:$H$30)=0,"—",SUMPRODUCT($D$10:$H$10,$D$30:$H$30)/SUMPRODUCT($D$21:$H$21,$D$30:$H$30)*100) | G41: =IF(SUMPRODUCT($D$21:$H$21,$D$31:$H$31)=0,"—",SUMPRODUCT($D$10:$H$10,$D$31:$H$31)/SUMPRODUCT($D$21:$H$21,$D$31:$H$31)*100) | H41: =SUMPRODUCT($D$10:$H$10,$D$32:$H$32) | I41: =SUMPRODUCT($D$21:$H$21,$D$32:$H$32) | J41: =COUNT('UI-6 กรอกคะแนน'!D9:H9)&"/5" | K41: =IF(COUNT($D41:$G41)=0,"—",IF($I41<100,"ยังตัดสินไม่ได้",IF($H41>='UI-1 รายวิชา'!$C$13,"ผ่าน","ไม่ผ่าน"))) | L41: =IF(COUNT($D41:$G41)=0,"ยังประเมินไม่ครบ",IF(SUMPRODUCT(--ISNUMBER($D41:$G41),--($D41:$G41<$D$33:$G$33))>0,"เสี่ยง (at-risk)","ปกติ"))
A42: 6 | B42: 65010006 | C42: นางสาวรัตนาภรณ์ ใจงาม | D42: =IF(SUMPRODUCT($D$22:$H$22,$D$28:$H$28)=0,"—",SUMPRODUCT($D$11:$H$11,$D$28:$H$28)/SUMPRODUCT($D$22:$H$22,$D$28:$H$28)*100) | E42: =IF(SUMPRODUCT($D$22:$H$22,$D$29:$H$29)=0,"—",SUMPRODUCT($D$11:$H$11,$D$29:$H$29)/SUMPRODUCT($D$22:$H$22,$D$29:$H$29)*100) | F42: =IF(SUMPRODUCT($D$22:$H$22,$D$30:$H$30)=0,"—",SUMPRODUCT($D$11:$H$11,$D$30:$H$30)/SUMPRODUCT($D$22:$H$22,$D$30:$H$30)*100) | G42: =IF(SUMPRODUCT($D$22:$H$22,$D$31:$H$31)=0,"—",SUMPRODUCT($D$11:$H$11,$D$31:$H$31)/SUMPRODUCT($D$22:$H$22,$D$31:$H$31)*100) | H42: =SUMPRODUCT($D$11:$H$11,$D$32:$H$32) | I42: =SUMPRODUCT($D$22:$H$22,$D$32:$H$32) | J42: =COUNT('UI-6 กรอกคะแนน'!D10:H10)&"/5" | K42: =IF(COUNT($D42:$G42)=0,"—",IF($I42<100,"ยังตัดสินไม่ได้",IF($H42>='UI-1 รายวิชา'!$C$13,"ผ่าน","ไม่ผ่าน"))) | L42: =IF(COUNT($D42:$G42)=0,"ยังประเมินไม่ครบ",IF(SUMPRODUCT(--ISNUMBER($D42:$G42),--($D42:$G42<$D$33:$G$33))>0,"เสี่ยง (at-risk)","ปกติ"))
A43: 7 | B43: 65010007 | C43: นายวรวุฒิ ชัยมงคล | D43: =IF(SUMPRODUCT($D$23:$H$23,$D$28:$H$28)=0,"—",SUMPRODUCT($D$12:$H$12,$D$28:$H$28)/SUMPRODUCT($D$23:$H$23,$D$28:$H$28)*100) | E43: =IF(SUMPRODUCT($D$23:$H$23,$D$29:$H$29)=0,"—",SUMPRODUCT($D$12:$H$12,$D$29:$H$29)/SUMPRODUCT($D$23:$H$23,$D$29:$H$29)*100) | F43: =IF(SUMPRODUCT($D$23:$H$23,$D$30:$H$30)=0,"—",SUMPRODUCT($D$12:$H$12,$D$30:$H$30)/SUMPRODUCT($D$23:$H$23,$D$30:$H$30)*100) | G43: =IF(SUMPRODUCT($D$23:$H$23,$D$31:$H$31)=0,"—",SUMPRODUCT($D$12:$H$12,$D$31:$H$31)/SUMPRODUCT($D$23:$H$23,$D$31:$H$31)*100) | H43: =SUMPRODUCT($D$12:$H$12,$D$32:$H$32) | I43: =SUMPRODUCT($D$23:$H$23,$D$32:$H$32) | J43: =COUNT('UI-6 กรอกคะแนน'!D11:H11)&"/5" | K43: =IF(COUNT($D43:$G43)=0,"—",IF($I43<100,"ยังตัดสินไม่ได้",IF($H43>='UI-1 รายวิชา'!$C$13,"ผ่าน","ไม่ผ่าน"))) | L43: =IF(COUNT($D43:$G43)=0,"ยังประเมินไม่ครบ",IF(SUMPRODUCT(--ISNUMBER($D43:$G43),--($D43:$G43<$D$33:$G$33))>0,"เสี่ยง (at-risk)","ปกติ"))
A44: 8 | B44: 65010008 | C44: นางสาวศิริพร แก้วมณี | D44: =IF(SUMPRODUCT($D$24:$H$24,$D$28:$H$28)=0,"—",SUMPRODUCT($D$13:$H$13,$D$28:$H$28)/SUMPRODUCT($D$24:$H$24,$D$28:$H$28)*100) | E44: =IF(SUMPRODUCT($D$24:$H$24,$D$29:$H$29)=0,"—",SUMPRODUCT($D$13:$H$13,$D$29:$H$29)/SUMPRODUCT($D$24:$H$24,$D$29:$H$29)*100) | F44: =IF(SUMPRODUCT($D$24:$H$24,$D$30:$H$30)=0,"—",SUMPRODUCT($D$13:$H$13,$D$30:$H$30)/SUMPRODUCT($D$24:$H$24,$D$30:$H$30)*100) | G44: =IF(SUMPRODUCT($D$24:$H$24,$D$31:$H$31)=0,"—",SUMPRODUCT($D$13:$H$13,$D$31:$H$31)/SUMPRODUCT($D$24:$H$24,$D$31:$H$31)*100) | H44: =SUMPRODUCT($D$13:$H$13,$D$32:$H$32) | I44: =SUMPRODUCT($D$24:$H$24,$D$32:$H$32) | J44: =COUNT('UI-6 กรอกคะแนน'!D12:H12)&"/5" | K44: =IF(COUNT($D44:$G44)=0,"—",IF($I44<100,"ยังตัดสินไม่ได้",IF($H44>='UI-1 รายวิชา'!$C$13,"ผ่าน","ไม่ผ่าน"))) | L44: =IF(COUNT($D44:$G44)=0,"ยังประเมินไม่ครบ",IF(SUMPRODUCT(--ISNUMBER($D44:$G44),--($D44:$G44<$D$33:$G$33))>0,"เสี่ยง (at-risk)","ปกติ"))
...

Sheet DB ทุกตาราง
A1: ฐานข้อมูล — ข้อมูลจริงที่เกิดจากหน้าจอ UI-1 ถึง UI-6
A2: ทั้ง 11 ตารางของ schema.prisma พร้อมแถวข้อมูลที่สอดคล้องกับหน้าจอทุกหน้าในไฟล์นี้
B4: User (3 แถว)
B5: เก็บอะไร: บัญชีผู้ใช้ระบบ (อาจารย์/แอดมิน) และบทบาทระดับระบบ
B6: ข้อมูลมาจาก: ผู้ดูแลระบบสร้างให้ ไม่ได้อยู่ในหน้าจอของอาจารย์
B7: id | C7: email | D7: name | E7: role | F7: isActive
B8: usr-01 | C8: admin@ftech.ac.th | D8: อ.ดร.สมชาย ใจดี | E8: ADMIN | F8: TRUE
B9: usr-02 | C9: wichai.k@ftech.ac.th | D9: ผศ.วิชัย คงเจริญ | E9: INSTRUCTOR | F9: TRUE
B10: usr-03 | C10: suda.p@ftech.ac.th | D10: อ.สุดา พรหมมา | E10: INSTRUCTOR | F10: TRUE
B11: รหัสผ่านเก็บเป็น passwordHash (argon2) เท่านั้น ไม่แสดงในตารางนี้และห้ามส่งออกทาง API
B14: Course (1 แถว)
B15: เก็บอะไร: รายวิชา — รากของลำดับชั้นข้อมูลทั้งหมด ไม่มีตารางใดอยู่เหนือกว่านี้
B16: ข้อมูลมาจาก: UI-1 รายวิชา
B17: id | C17: code | D17: name | E17: semester | F17: year | G17: section | H17: gradingType | I17: passCriteria | J17: classTarget
B18: crs-01 | C18: 90641002 | D18: ระบบฐานข้อมูล | E18: 1 | F18: 2568 | G18: 01 | H18: LETTER | I18: 60 | J18: 70
B21: CourseInstructor (2 แถว)
B22: เก็บอะไร: ใครสอนวิชาไหน ในบทบาทอะไร (ตารางเชื่อม User ↔ Course แบบ M:N)
B23: ข้อมูลมาจาก: หน้าจอมอบหมายผู้สอน (สิทธิ์ ADMIN)
B24: id | C24: courseId | D24: userId | E24: role | F24: assignedAt
B25: ci-01 | C25: crs-01 | D25: usr-02 | E25: LEAD | F25: 2568-06-01
B26: ci-02 | C26: crs-01 | D26: usr-03 | E26: CO | F26: 2568-06-01
B27: 1 รายวิชามี LEAD ได้ไม่เกิน 1 คน — บังคับด้วย partial unique index ที่ Postgres (DC-07)
B30: CLO (4 แถว)
B31: เก็บอะไร: ผลลัพธ์การเรียนรู้ที่คาดหวังของรายวิชา พร้อมเกณฑ์ผ่านรายคน
B32: ข้อมูลมาจาก: UI-2 CLO
B33: id | C33: courseId | D33: number | E33: description | F33: threshold
B34: clo-01 | C34: crs-01 | D34: 1 | E34: ออกแบบฐานข้อมูลเชิงสัมพันธ์จากโจทย์ที่กำหนดได้ | F34: 60
B35: clo-02 | C35: crs-01 | D35: 2 | E35: เขียนคำสั่ง SQL เพื่อสืบค้นและจัดการข้อมูลได้ | F35: 60
B36: clo-03 | C36: crs-01 | D36: 3 | E36: ทำ Normalization ถึงระดับ 3NF ได้ถูกต้อง | F36: 65
B37: clo-04 | C37: crs-01 | D37: 4 | E37: ทำงานเป็นทีมและนำเสนอผลงานได้ | F37: 60
B38: ไม่มีคอลัมน์ weight — น้ำหนักของ CLO เป็นค่าคำนวณจาก AssessmentCriteria (CR-02)
B41: BehavioralObjective (7 แถว)
B42: เก็บอะไร: จุดประสงค์เชิงพฤติกรรมที่ย่อยลงมาจาก CLO แต่ละข้อ
B43: ข้อมูลมาจาก: UI-2 CLO (บล็อกล่าง)
B44: id | C44: cloId | D44: number | E44: description
B45: obj-01 | C45: clo-01 | D45: 1 | E45: เขียน ER-Diagram จากความต้องการของผู้ใช้ได้
B46: obj-02 | C46: clo-01 | D46: 2 | E46: แปลง ER-Diagram เป็นตารางเชิงสัมพันธ์ได้
B47: obj-03 | C47: clo-02 | D47: 1 | E47: เขียนคำสั่ง SELECT พร้อม JOIN หลายตารางได้
B48: obj-04 | C48: clo-02 | D48: 2 | E48: ใช้ subquery และฟังก์ชันรวม (aggregate) ได้
B49: obj-05 | C49: clo-03 | D49: 1 | E49: ระบุ functional dependency ของตารางได้
...

Sheet UI to DB Mapping
A1: แผนที่ระดับช่องกรอก — UI → ตาราง.คอลัมน์
A2: ใช้ตอบคำถามว่า 'ช่องนี้บนหน้าจอ ไปโผล่ที่ไหนในฐานข้อมูล' และ 'ค่านี้ใครเป็นคนคำนวณ'
B4: หน้าจอ | C4: ช่องกรอก / สิ่งที่เห็น | D4: ตาราง | E4: คอลัมน์ | F4: หมายเหตุ
B5: UI-1 รายวิชา | C5: รหัสวิชา / ภาค / ปี / กลุ่ม | D5: Course | E5: code, semester, year, section | F5: 4 ค่านี้รวมกันต้องไม่ซ้ำทั้งระบบ (FR-21)
B6: UI-1 รายวิชา | C6: เกณฑ์ผ่านรายวิชา | D6: Course | E6: passCriteria | F6: CR-05 ใช้ตัดสินว่านักศึกษาผ่านวิชาหรือไม่
B7: UI-1 รายวิชา | C7: เป้าหมายระดับชั้น | D7: Course | E7: classTarget | F7: CR-04 ใช้ตัดสินว่า CLO บรรลุหรือไม่
B8: UI-2 CLO | C8: คำอธิบาย CLO | D8: CLO | E8: description
B9: UI-2 CLO | C9: เกณฑ์ผ่านของ CLO | D9: CLO | E9: threshold | F9: เกณฑ์รายบุคคล ไม่ใช่ระดับชั้น
B10: UI-2 CLO | C10: จุดประสงค์เชิงพฤติกรรม | D10: BehavioralObjective | E10: cloId, number, description | F10: ไม่กระทบคะแนนที่คำนวณ (FR-35)
B11: UI-3 กิจกรรม | C11: ชื่อกิจกรรม / วิธีประเมิน | D11: Activity | E11: name, method
B12: UI-3 กิจกรรม | C12: คะแนนเต็ม | D12: Activity | E12: maxScore | F12: ต้อง > 0 บังคับที่ฐานข้อมูล (DC-03)
B13: UI-3 กิจกรรม | C13: น้ำหนักต่อวิชา | D13: Activity | E13: weight | F13: รวมทุกกิจกรรมในวิชา = 100 (CR-01)
B14: UI-4 Mapping | C14: ตัวเลขในเมทริกซ์ (> 0) | D14: AssessmentCriteria | E14: activityId, cloId, weight | F14: ช่องที่เป็น 0 ไม่สร้างแถว
B15: UI-4 Mapping | C15: แถว 'น้ำหนักของ CLO' | D15: — ไม่เก็บ — | E15: คำนวณ (CR-02) | F15: ถ้าเก็บซ้ำจะมีวันที่ค่าสองที่ไม่ตรงกัน
B16: UI-5 รายชื่อ | C16: รหัสนักศึกษา / ชื่อ | D16: Student | E16: studentCode, name, courseId | F16: ห้ามซ้ำภายในวิชาเดียวกัน (FR-51)
B17: UI-6 กรอกคะแนน | C17: ตัวเลขคะแนนในตาราง | D17: Score | E17: studentId, activityId, score | F17: ช่องว่างไม่สร้างแถว · 0 สร้างแถว (FR-62)
B18: UI-6 กรอกคะแนน | C18: การอัปโหลดไฟล์ | D18: ScoreUploadLog | E18: fileName, recordsOk, recordsFail | F18: บันทึกทุกครั้งแม้ไฟล์ล้มเหลวทั้งไฟล์ (FR-71)
B19: UI-7 ผลลัพธ์ CLO | C19: คะแนน CLO รายบุคคล | D19: — ไม่เก็บ — | E19: คำนวณ (CR-03) | F19: อ่านจาก Score + AssessmentCriteria สด ๆ
B20: UI-7 ผลลัพธ์ CLO | C20: คะแนนรวม / ผ่านวิชา | D20: — ไม่เก็บ — | E20: คำนวณ (CR-05)
B21: UI-7 ผลลัพธ์ CLO | C21: Attainment / บรรลุหรือไม่ | D21: — ไม่เก็บ — | E21: คำนวณ (CR-04)
B22: UI-7 ผลลัพธ์ CLO | C22: สถานะ at-risk | D22: — ไม่เก็บ — | E22: คำนวณ (CR-05) | F22: มี CLO อย่างน้อย 1 ข้อต่ำกว่า threshold
B24: แถวสีเขียวคือค่าที่ 'ไม่มีตารางเก็บ' — ระบบคำนวณใหม่ทุกครั้งที่แสดงผล ถ้าวันหนึ่งมีคนเสนอให้เก็บลงตารางเพื่อความเร็ว ต้องตอบให้ได้ก่อนว่าจะทำให้ค่าตรงกับคะแนนดิบเสมอได้อย่างไร
